2022-01-28 15:23:04,400 - ERROR - Some error happened during scraping
2022-01-30 09:49:20,807 - ERROR - Timeout in tunneling
2022-01-30 10:10:47,173 - ERROR - Timeout in tunneling
2022-01-30 10:23:34,108 - ERROR - Timeout in tunneling
2022-01-30 15:25:34,750 - ERROR - Timeout in tunneling
2022-01-30 15:33:00,598 - ERROR - Timeout in tunneling
2022-01-30 15:34:30,520 - ERROR - Timeout in tunneling
2022-01-30 15:36:44,823 - ERROR - Timeout in tunneling
2022-01-30 15:39:43,444 - ERROR - Timeout in tunneling
2022-01-30 15:44:15,965 - ERROR - NoneType: None

2022-01-30 15:45:33,981 - ERROR - <function format_exc at 0x7f823d369700>
2022-01-30 15:46:16,224 - ERROR - Traceback (most recent call last):
  File "/home/aldo/tweakersClone/src/webScraperCommon.py", line 64, in _tunnelToDatabaseServer
    time.sleep(14)
  File "/home/aldo/tweakersClone/src/venv_server/lib/python3.9/site-packages/interruptingcow/__init__.py", line 74, in handler
    raise exception
RuntimeError

2022-01-30 15:49:42,825 - ERROR - Timeout in tunneling, traceback: 
Traceback (most recent call last):
  File "/home/aldo/tweakersClone/src/webScraperCommon.py", line 64, in _tunnelToDatabaseServer
    time.sleep(14)
  File "/home/aldo/tweakersClone/src/venv_server/lib/python3.9/site-packages/interruptingcow/__init__.py", line 74, in handler
    raise exception
RuntimeError

2022-01-30 15:54:03,249 - ERROR - Timeout in tunneling, traceback: 
Traceback (most recent call last):
  File "/home/aldo/tweakersClone/src/webScraperCommon.py", line 64, in _tunnelToDatabaseServer
    time.sleep(14)
  File "/home/aldo/tweakersClone/src/venv_server/lib/python3.9/site-packages/interruptingcow/__init__.py", line 74, in handler
    raise exception
RuntimeError

2022-01-30 15:55:41,227 - ERROR - Timeout in tunneling, traceback: 
Traceback (most recent call last):
  File "/home/aldo/tweakersClone/src/webScraperCommon.py", line 64, in _tunnelToDatabaseServer
    time.sleep(14)
  File "/home/aldo/tweakersClone/src/venv_server/lib/python3.9/site-packages/interruptingcow/__init__.py", line 74, in handler
    raise exception
RuntimeError

2022-01-30 16:44:53,121 - ERROR - Timeout in tunneling, traceback: 
Traceback (most recent call last):
  File "/home/aldo/tweakersClone/src/webScraperCommon.py", line 64, in _tunnelToDatabaseServer
    time.sleep(14)
  File "/home/aldo/tweakersClone/src/venv_server/lib/python3.9/site-packages/interruptingcow/__init__.py", line 74, in handler
    raise exception
RuntimeError

2022-01-30 16:44:53,122 - ERROR - dbURI not attainable, error: Traceback (most recent call last):
  File "/home/aldo/tweakersClone/src/visualizeScrapedData.py", line 62, in <module>
    dbURI = SSHTunnelOperations("aldosebastian","25803conan","mysql","dateItemPrice").getURI()
  File "/home/aldo/tweakersClone/src/webScraperCommon.py", line 43, in getURI
    {self._tunnelToDatabaseServer().local_bind_port}/{self.username}${self.schema}'
  File "/home/aldo/tweakersClone/src/webScraperCommon.py", line 75, in _tunnelToDatabaseServer
    raise tunnelingTimeoutException(msg = exceptionMsg)
customExceptions.tunnelingTimeoutException: Traceback (most recent call last):
  File "/home/aldo/tweakersClone/src/webScraperCommon.py", line 64, in _tunnelToDatabaseServer
    time.sleep(14)
  File "/home/aldo/tweakersClone/src/venv_server/lib/python3.9/site-packages/interruptingcow/__init__.py", line 74, in handler
    raise exception
RuntimeError


2022-01-30 17:50:19,243 - ERROR - Credentials of database not available, traceback: 
Traceback (most recent call last):
  File "/home/aldo/tweakersClone/src/coolblueScraper.py", line 47, in main
    password = os.environ["tweakersClonePasswor"]
  File "/usr/lib/python3.9/os.py", line 679, in __getitem__
    raise KeyError(key) from None
KeyError: 'tweakersClonePasswor'

2022-01-31 04:03:03,772 - ERROR - Credentials of database not available, traceback: 
Traceback (most recent call last):
  File "/home/aldo/tweakersClone/src/coolblueScraper.py", line 46, in main
    username = os.environ["tweakersCloneUsername"]
  File "/usr/lib/python3.9/os.py", line 679, in __getitem__
    raise KeyError(key) from None
KeyError: 'tweakersCloneUsername'

2022-01-31 07:21:59,106 - ERROR - Credentials of database not available, traceback: 
Traceback (most recent call last):
  File "/home/aldo/tweakersClone/src/coolblueScraper.py", line 47, in main
    password = os.environ["tweakersClonePasswod"]
  File "/usr/lib/python3.9/os.py", line 679, in __getitem__
    raise KeyError(key) from None
KeyError: 'tweakersClonePasswod'

2022-01-31 07:30:27,603 - INFO - Attempt 1 of activating geckodriver
2022-01-31 07:30:55,393 - ERROR - dbURI not attainable, : 
Traceback (most recent call last):
  File "/home/aldo/tweakersClone/src/webScraperCommon.py", line 66, in _tunnelToDatabaseServer
    time.sleep(14)
  File "/home/aldo/tweakersClone/src/venv_server/lib/python3.9/site-packages/interruptingcow/__init__.py", line 74, in handler
    raise exception
RuntimeError

During handling of the above exception, another exception occurred:

Traceback (most recent call last):
  File "/home/aldo/tweakersClone/src/visualizeScrapedData.py", line 62, in <module>
    dbURI = SSHTunnelOperations("aldosebastian","25803conan","mysql","dateItemPrice").getURI()
  File "/home/aldo/tweakersClone/src/webScraperCommon.py", line 45, in getURI
    {self._tunnelToDatabaseServer().local_bind_port}/{self.username}${self.schema}'
  File "/home/aldo/tweakersClone/src/webScraperCommon.py", line 73, in _tunnelToDatabaseServer
    scraperLogger(level = "ERROR", msg = f"SSH tunneling attempt {i} FAILED \n" \
TypeError: can only concatenate str (not "NoneType") to str

2022-01-31 09:22:57,593 - INFO - Attempt 1 of activating geckodriver
2022-01-31 09:24:03,637 - INFO - Attempt 1 of activating geckodriver
2022-01-31 09:24:10,665 - INFO - geckodriver successfully activated
2022-01-31 09:24:15,105 - ERROR - Some error happened during scraping: Traceback (most recent call last):
  File "/home/aldo/tweakersClone/src/webScraperCommon.py", line 217, in scrapeStore
    self.extract_record(self.searchTerm,self.soup,self.itemPriceLink,self.storeName)
TypeError: extract_record() missing 1 required positional argument: 'storeName'

2022-01-31 10:34:00,369 - ERROR - Credentials of database not available, traceback: 
Traceback (most recent call last):
  File "src/amazonScraper.py", line 46, in main
    username = os.environ["tweakersCloneUsername"]
  File "C:\Users\320145763\AppData\Local\Programs\Python\Python39\lib\os.py", line 679, in __getitem__
    raise KeyError(key) from None
KeyError: 'tweakersCloneUsername'

2022-01-31 10:35:09,672 - ERROR - Credentials of database not available, traceback: 
Traceback (most recent call last):
  File "src/amazonScraper.py", line 46, in main
    username = os.environ["tweakersCloneUsername"]
  File "C:\Users\320145763\AppData\Local\Programs\Python\Python39\lib\os.py", line 679, in __getitem__
    raise KeyError(key) from None
KeyError: 'tweakersCloneUsername'

2022-01-31 10:35:49,890 - ERROR - Credentials of database not available, traceback: 
Traceback (most recent call last):
  File "src/amazonScraper.py", line 46, in main
    username = os.environ["tweakersCloneUsername"]
  File "C:\Users\320145763\AppData\Local\Programs\Python\Python39\lib\os.py", line 679, in __getitem__
    raise KeyError(key) from None
KeyError: 'tweakersCloneUsername'

2022-01-31 10:41:15,401 - ERROR - Credentials of database not available, traceback: 
Traceback (most recent call last):
  File "src/amazonScraper.py", line 46, in main
    username = os.environ["tweakersCloneUsername"]
  File "C:\Users\320145763\AppData\Local\Programs\Python\Python39\lib\os.py", line 679, in __getitem__
    raise KeyError(key) from None
KeyError: 'tweakersCloneUsername'

2022-01-31 10:47:21,317 - INFO - Attempt 1 of activating geckodriver
2022-01-31 10:47:26,492 - INFO - geckodriver successfully activated
2022-01-31 10:47:43,811 - INFO - Attempt 1 of activating geckodriver
2022-01-31 10:47:49,010 - INFO - geckodriver successfully activated
2022-01-31 11:28:23,110 - INFO - Attempt 1 of activating geckodriver
2022-01-31 11:28:28,299 - INFO - geckodriver successfully activated
2022-01-31 11:30:03,815 - INFO - Attempt 1 of activating geckodriver
2022-01-31 11:30:08,999 - INFO - geckodriver successfully activated
2022-01-31 11:30:48,329 - INFO - Attempt 1 of activating geckodriver
2022-01-31 11:30:54,002 - INFO - geckodriver successfully activated
2022-01-31 11:45:21,127 - INFO - Attempt 1 of activating geckodriver
2022-01-31 11:45:26,328 - INFO - geckodriver successfully activated
2022-01-31 11:49:27,057 - INFO - Attempt 1 of activating geckodriver
2022-01-31 11:49:32,752 - INFO - geckodriver successfully activated
2022-01-31 11:50:17,627 - INFO - Attempt 1 of activating geckodriver
2022-01-31 11:50:23,356 - INFO - geckodriver successfully activated
2022-01-31 11:59:46,206 - INFO - Attempt 1 of activating geckodriver
2022-01-31 11:59:51,387 - INFO - geckodriver successfully activated
2022-01-31 11:59:57,275 - ERROR - Some error happened during scraping: Traceback (most recent call last):
  File "C:\Users\320145763\OneDrive\job and portfolio\portfolio and programming\onlineWebscraper\src\webScraperCommon.py", line 229, in scrapeStore
    self.extract_record(self.searchTerm,self.soup,self.itemPriceLink,self.storeName)
TypeError: extract_record() missing 1 required positional argument: 'storeName'

2022-01-31 12:02:10,761 - INFO - Attempt 1 of activating geckodriver
2022-01-31 12:02:16,440 - INFO - geckodriver successfully activated
