2022-01-28 15:23:04,400 - ERROR - Some error happened during scraping
2022-01-30 09:49:20,807 - ERROR - Timeout in tunneling
2022-01-30 10:10:47,173 - ERROR - Timeout in tunneling
2022-01-30 10:23:34,108 - ERROR - Timeout in tunneling
2022-01-30 15:25:34,750 - ERROR - Timeout in tunneling
2022-01-30 15:33:00,598 - ERROR - Timeout in tunneling
2022-01-30 15:34:30,520 - ERROR - Timeout in tunneling
2022-01-30 15:36:44,823 - ERROR - Timeout in tunneling
2022-01-30 15:39:43,444 - ERROR - Timeout in tunneling
2022-01-30 15:44:15,965 - ERROR - NoneType: None

2022-01-30 15:45:33,981 - ERROR - <function format_exc at 0x7f823d369700>
2022-01-30 15:46:16,224 - ERROR - Traceback (most recent call last):
  File "/home/aldo/tweakersClone/src/webScraperCommon.py", line 64, in _tunnelToDatabaseServer
    time.sleep(14)
  File "/home/aldo/tweakersClone/src/venv_server/lib/python3.9/site-packages/interruptingcow/__init__.py", line 74, in handler
    raise exception
RuntimeError

2022-01-30 15:49:42,825 - ERROR - Timeout in tunneling, traceback: 
Traceback (most recent call last):
  File "/home/aldo/tweakersClone/src/webScraperCommon.py", line 64, in _tunnelToDatabaseServer
    time.sleep(14)
  File "/home/aldo/tweakersClone/src/venv_server/lib/python3.9/site-packages/interruptingcow/__init__.py", line 74, in handler
    raise exception
RuntimeError

2022-01-30 15:54:03,249 - ERROR - Timeout in tunneling, traceback: 
Traceback (most recent call last):
  File "/home/aldo/tweakersClone/src/webScraperCommon.py", line 64, in _tunnelToDatabaseServer
    time.sleep(14)
  File "/home/aldo/tweakersClone/src/venv_server/lib/python3.9/site-packages/interruptingcow/__init__.py", line 74, in handler
    raise exception
RuntimeError

2022-01-30 15:55:41,227 - ERROR - Timeout in tunneling, traceback: 
Traceback (most recent call last):
  File "/home/aldo/tweakersClone/src/webScraperCommon.py", line 64, in _tunnelToDatabaseServer
    time.sleep(14)
  File "/home/aldo/tweakersClone/src/venv_server/lib/python3.9/site-packages/interruptingcow/__init__.py", line 74, in handler
    raise exception
RuntimeError

2022-01-30 16:44:53,121 - ERROR - Timeout in tunneling, traceback: 
Traceback (most recent call last):
  File "/home/aldo/tweakersClone/src/webScraperCommon.py", line 64, in _tunnelToDatabaseServer
    time.sleep(14)
  File "/home/aldo/tweakersClone/src/venv_server/lib/python3.9/site-packages/interruptingcow/__init__.py", line 74, in handler
    raise exception
RuntimeError

2022-01-30 16:44:53,122 - ERROR - dbURI not attainable, error: Traceback (most recent call last):
  File "/home/aldo/tweakersClone/src/visualizeScrapedData.py", line 62, in <module>
    dbURI = SSHTunnelOperations("aldosebastian","25803conan","mysql","dateItemPrice").getURI()
  File "/home/aldo/tweakersClone/src/webScraperCommon.py", line 43, in getURI
    {self._tunnelToDatabaseServer().local_bind_port}/{self.username}${self.schema}'
  File "/home/aldo/tweakersClone/src/webScraperCommon.py", line 75, in _tunnelToDatabaseServer
    raise tunnelingTimeoutException(msg = exceptionMsg)
customExceptions.tunnelingTimeoutException: Traceback (most recent call last):
  File "/home/aldo/tweakersClone/src/webScraperCommon.py", line 64, in _tunnelToDatabaseServer
    time.sleep(14)
  File "/home/aldo/tweakersClone/src/venv_server/lib/python3.9/site-packages/interruptingcow/__init__.py", line 74, in handler
    raise exception
RuntimeError


2022-01-30 17:50:19,243 - ERROR - Credentials of database not available, traceback: 
Traceback (most recent call last):
  File "/home/aldo/tweakersClone/src/coolblueScraper.py", line 47, in main
    password = os.environ["tweakersClonePasswor"]
  File "/usr/lib/python3.9/os.py", line 679, in __getitem__
    raise KeyError(key) from None
KeyError: 'tweakersClonePasswor'

2022-01-31 04:03:03,772 - ERROR - Credentials of database not available, traceback: 
Traceback (most recent call last):
  File "/home/aldo/tweakersClone/src/coolblueScraper.py", line 46, in main
    username = os.environ["tweakersCloneUsername"]
  File "/usr/lib/python3.9/os.py", line 679, in __getitem__
    raise KeyError(key) from None
KeyError: 'tweakersCloneUsername'

2022-01-31 07:21:59,106 - ERROR - Credentials of database not available, traceback: 
Traceback (most recent call last):
  File "/home/aldo/tweakersClone/src/coolblueScraper.py", line 47, in main
    password = os.environ["tweakersClonePasswod"]
  File "/usr/lib/python3.9/os.py", line 679, in __getitem__
    raise KeyError(key) from None
KeyError: 'tweakersClonePasswod'

2022-01-31 07:30:27,603 - INFO - Attempt 1 of activating geckodriver
2022-01-31 07:30:55,393 - ERROR - dbURI not attainable, : 
Traceback (most recent call last):
  File "/home/aldo/tweakersClone/src/webScraperCommon.py", line 66, in _tunnelToDatabaseServer
    time.sleep(14)
  File "/home/aldo/tweakersClone/src/venv_server/lib/python3.9/site-packages/interruptingcow/__init__.py", line 74, in handler
    raise exception
RuntimeError

During handling of the above exception, another exception occurred:

Traceback (most recent call last):
  File "/home/aldo/tweakersClone/src/visualizeScrapedData.py", line 62, in <module>
    dbURI = SSHTunnelOperations("aldosebastian","25803conan","mysql","dateItemPrice").getURI()
  File "/home/aldo/tweakersClone/src/webScraperCommon.py", line 45, in getURI
    {self._tunnelToDatabaseServer().local_bind_port}/{self.username}${self.schema}'
  File "/home/aldo/tweakersClone/src/webScraperCommon.py", line 73, in _tunnelToDatabaseServer
    scraperLogger(level = "ERROR", msg = f"SSH tunneling attempt {i} FAILED \n" \
TypeError: can only concatenate str (not "NoneType") to str

2022-01-31 09:22:57,593 - INFO - Attempt 1 of activating geckodriver
2022-01-31 09:24:03,637 - INFO - Attempt 1 of activating geckodriver
2022-01-31 09:24:10,665 - INFO - geckodriver successfully activated
2022-01-31 09:24:15,105 - ERROR - Some error happened during scraping: Traceback (most recent call last):
  File "/home/aldo/tweakersClone/src/webScraperCommon.py", line 217, in scrapeStore
    self.extract_record(self.searchTerm,self.soup,self.itemPriceLink,self.storeName)
TypeError: extract_record() missing 1 required positional argument: 'storeName'

2022-01-31 10:34:00,369 - ERROR - Credentials of database not available, traceback: 
Traceback (most recent call last):
  File "src/amazonScraper.py", line 46, in main
    username = os.environ["tweakersCloneUsername"]
  File "C:\Users\320145763\AppData\Local\Programs\Python\Python39\lib\os.py", line 679, in __getitem__
    raise KeyError(key) from None
KeyError: 'tweakersCloneUsername'

2022-01-31 10:35:09,672 - ERROR - Credentials of database not available, traceback: 
Traceback (most recent call last):
  File "src/amazonScraper.py", line 46, in main
    username = os.environ["tweakersCloneUsername"]
  File "C:\Users\320145763\AppData\Local\Programs\Python\Python39\lib\os.py", line 679, in __getitem__
    raise KeyError(key) from None
KeyError: 'tweakersCloneUsername'

2022-01-31 10:35:49,890 - ERROR - Credentials of database not available, traceback: 
Traceback (most recent call last):
  File "src/amazonScraper.py", line 46, in main
    username = os.environ["tweakersCloneUsername"]
  File "C:\Users\320145763\AppData\Local\Programs\Python\Python39\lib\os.py", line 679, in __getitem__
    raise KeyError(key) from None
KeyError: 'tweakersCloneUsername'

2022-01-31 10:41:15,401 - ERROR - Credentials of database not available, traceback: 
Traceback (most recent call last):
  File "src/amazonScraper.py", line 46, in main
    username = os.environ["tweakersCloneUsername"]
  File "C:\Users\320145763\AppData\Local\Programs\Python\Python39\lib\os.py", line 679, in __getitem__
    raise KeyError(key) from None
KeyError: 'tweakersCloneUsername'

2022-01-31 10:47:21,317 - INFO - Attempt 1 of activating geckodriver
2022-01-31 10:47:26,492 - INFO - geckodriver successfully activated
2022-01-31 10:47:43,811 - INFO - Attempt 1 of activating geckodriver
2022-01-31 10:47:49,010 - INFO - geckodriver successfully activated
2022-01-31 11:28:23,110 - INFO - Attempt 1 of activating geckodriver
2022-01-31 11:28:28,299 - INFO - geckodriver successfully activated
2022-01-31 11:30:03,815 - INFO - Attempt 1 of activating geckodriver
2022-01-31 11:30:08,999 - INFO - geckodriver successfully activated
2022-01-31 11:30:48,329 - INFO - Attempt 1 of activating geckodriver
2022-01-31 11:30:54,002 - INFO - geckodriver successfully activated
2022-01-31 11:45:21,127 - INFO - Attempt 1 of activating geckodriver
2022-01-31 11:45:26,328 - INFO - geckodriver successfully activated
2022-01-31 11:49:27,057 - INFO - Attempt 1 of activating geckodriver
2022-01-31 11:49:32,752 - INFO - geckodriver successfully activated
2022-01-31 11:50:17,627 - INFO - Attempt 1 of activating geckodriver
2022-01-31 11:50:23,356 - INFO - geckodriver successfully activated
2022-01-31 11:59:46,206 - INFO - Attempt 1 of activating geckodriver
2022-01-31 11:59:51,387 - INFO - geckodriver successfully activated
2022-01-31 11:59:57,275 - ERROR - Some error happened during scraping: Traceback (most recent call last):
  File "C:\Users\320145763\OneDrive\job and portfolio\portfolio and programming\onlineWebscraper\src\webScraperCommon.py", line 229, in scrapeStore
    self.extract_record(self.searchTerm,self.soup,self.itemPriceLink,self.storeName)
TypeError: extract_record() missing 1 required positional argument: 'storeName'

2022-01-31 12:02:10,761 - INFO - Attempt 1 of activating geckodriver
2022-01-31 12:02:16,440 - INFO - geckodriver successfully activated
2022-02-01 04:03:04,324 - ERROR - Credentials of database not available, traceback: 
Traceback (most recent call last):
  File "/home/aldo/tweakersClone/src/coolblueScraper.py", line 46, in main
    username = os.environ["tweakersCloneUsername"]
  File "/usr/lib/python3.9/os.py", line 679, in __getitem__
    raise KeyError(key) from None
KeyError: 'tweakersCloneUsername'

2022-02-01 14:16:59,354 - INFO - Attempt 1 of activating geckodriver
2022-02-01 14:21:43,695 - INFO - Attempt 1 of activating geckodriver
2022-02-01 14:21:45,303 - ERROR - Geckodriver activation attempt 2 FAILED 
Traceback (most recent call last):
  File "/home/aldo/tweakersClone/src/webScraperCommon.py", line 209, in __init__
    self.driver = webdriver.Firefox(executable_path=self.pwd + self.geckodriverExe, options=self.firefox_options)
  File "/home/aldo/tweakersClone/src/venv_server/lib/python3.9/site-packages/selenium/webdriver/firefox/webdriver.py", line 154, in __init__
    RemoteWebDriver.__init__(
  File "/home/aldo/tweakersClone/src/venv_server/lib/python3.9/site-packages/selenium/webdriver/remote/webdriver.py", line 154, in __init__
    self.start_session(desired_capabilities, browser_profile)
  File "/home/aldo/tweakersClone/src/venv_server/lib/python3.9/site-packages/selenium/webdriver/remote/webdriver.py", line 243, in start_session
    response = self.execute(Command.NEW_SESSION, parameters)
  File "/home/aldo/tweakersClone/src/venv_server/lib/python3.9/site-packages/selenium/webdriver/remote/webdriver.py", line 311, in execute
    self.error_handler.check_response(response)
  File "/home/aldo/tweakersClone/src/venv_server/lib/python3.9/site-packages/selenium/webdriver/remote/errorhandler.py", line 237, in check_response
    raise exception_class(message, screen, stacktrace)
selenium.common.exceptions.WebDriverException: Message: Process unexpectedly closed with status 1


2022-02-01 14:21:45,306 - INFO - Attempt 2 of activating geckodriver
2022-02-01 14:21:46,803 - ERROR - Geckodriver activation attempt 3 FAILED 
Traceback (most recent call last):
  File "/home/aldo/tweakersClone/src/webScraperCommon.py", line 209, in __init__
    self.driver = webdriver.Firefox(executable_path=self.pwd + self.geckodriverExe, options=self.firefox_options)
  File "/home/aldo/tweakersClone/src/venv_server/lib/python3.9/site-packages/selenium/webdriver/firefox/webdriver.py", line 154, in __init__
    RemoteWebDriver.__init__(
  File "/home/aldo/tweakersClone/src/venv_server/lib/python3.9/site-packages/selenium/webdriver/remote/webdriver.py", line 154, in __init__
    self.start_session(desired_capabilities, browser_profile)
  File "/home/aldo/tweakersClone/src/venv_server/lib/python3.9/site-packages/selenium/webdriver/remote/webdriver.py", line 243, in start_session
    response = self.execute(Command.NEW_SESSION, parameters)
  File "/home/aldo/tweakersClone/src/venv_server/lib/python3.9/site-packages/selenium/webdriver/remote/webdriver.py", line 311, in execute
    self.error_handler.check_response(response)
  File "/home/aldo/tweakersClone/src/venv_server/lib/python3.9/site-packages/selenium/webdriver/remote/errorhandler.py", line 237, in check_response
    raise exception_class(message, screen, stacktrace)
selenium.common.exceptions.WebDriverException: Message: Process unexpectedly closed with status 1


2022-02-01 14:21:46,808 - INFO - Attempt 3 of activating geckodriver
2022-02-01 14:21:48,200 - ERROR - Geckodriver activation attempt 4 FAILED 
Traceback (most recent call last):
  File "/home/aldo/tweakersClone/src/webScraperCommon.py", line 209, in __init__
    self.driver = webdriver.Firefox(executable_path=self.pwd + self.geckodriverExe, options=self.firefox_options)
  File "/home/aldo/tweakersClone/src/venv_server/lib/python3.9/site-packages/selenium/webdriver/firefox/webdriver.py", line 154, in __init__
    RemoteWebDriver.__init__(
  File "/home/aldo/tweakersClone/src/venv_server/lib/python3.9/site-packages/selenium/webdriver/remote/webdriver.py", line 154, in __init__
    self.start_session(desired_capabilities, browser_profile)
  File "/home/aldo/tweakersClone/src/venv_server/lib/python3.9/site-packages/selenium/webdriver/remote/webdriver.py", line 243, in start_session
    response = self.execute(Command.NEW_SESSION, parameters)
  File "/home/aldo/tweakersClone/src/venv_server/lib/python3.9/site-packages/selenium/webdriver/remote/webdriver.py", line 311, in execute
    self.error_handler.check_response(response)
  File "/home/aldo/tweakersClone/src/venv_server/lib/python3.9/site-packages/selenium/webdriver/remote/errorhandler.py", line 237, in check_response
    raise exception_class(message, screen, stacktrace)
selenium.common.exceptions.WebDriverException: Message: Process unexpectedly closed with status 1


2022-02-01 14:21:48,208 - ERROR - Some error happened during scraping: Traceback (most recent call last):
  File "/home/aldo/tweakersClone/src/webScraperCommon.py", line 233, in scrapeStore
    self.driver.get(self._get_url(page))
AttributeError: 'Scrape' object has no attribute 'driver'

2022-02-01 14:22:47,768 - INFO - Attempt 1 of activating geckodriver
2022-02-01 14:22:49,631 - ERROR - Geckodriver activation attempt 2 FAILED 
Traceback (most recent call last):
  File "/home/aldo/tweakersClone/src/webScraperCommon.py", line 209, in __init__
    self.driver = webdriver.Firefox(executable_path=self.pwd + self.geckodriverExe, options=self.firefox_options)
  File "/home/aldo/tweakersClone/src/venv_server/lib/python3.9/site-packages/selenium/webdriver/firefox/webdriver.py", line 154, in __init__
    RemoteWebDriver.__init__(
  File "/home/aldo/tweakersClone/src/venv_server/lib/python3.9/site-packages/selenium/webdriver/remote/webdriver.py", line 154, in __init__
    self.start_session(desired_capabilities, browser_profile)
  File "/home/aldo/tweakersClone/src/venv_server/lib/python3.9/site-packages/selenium/webdriver/remote/webdriver.py", line 243, in start_session
    response = self.execute(Command.NEW_SESSION, parameters)
  File "/home/aldo/tweakersClone/src/venv_server/lib/python3.9/site-packages/selenium/webdriver/remote/webdriver.py", line 311, in execute
    self.error_handler.check_response(response)
  File "/home/aldo/tweakersClone/src/venv_server/lib/python3.9/site-packages/selenium/webdriver/remote/errorhandler.py", line 237, in check_response
    raise exception_class(message, screen, stacktrace)
selenium.common.exceptions.WebDriverException: Message: Process unexpectedly closed with status 1


2022-02-01 14:22:49,639 - INFO - Attempt 2 of activating geckodriver
2022-02-01 14:22:51,138 - ERROR - Geckodriver activation attempt 3 FAILED 
Traceback (most recent call last):
  File "/home/aldo/tweakersClone/src/webScraperCommon.py", line 209, in __init__
    self.driver = webdriver.Firefox(executable_path=self.pwd + self.geckodriverExe, options=self.firefox_options)
  File "/home/aldo/tweakersClone/src/venv_server/lib/python3.9/site-packages/selenium/webdriver/firefox/webdriver.py", line 154, in __init__
    RemoteWebDriver.__init__(
  File "/home/aldo/tweakersClone/src/venv_server/lib/python3.9/site-packages/selenium/webdriver/remote/webdriver.py", line 154, in __init__
    self.start_session(desired_capabilities, browser_profile)
  File "/home/aldo/tweakersClone/src/venv_server/lib/python3.9/site-packages/selenium/webdriver/remote/webdriver.py", line 243, in start_session
    response = self.execute(Command.NEW_SESSION, parameters)
  File "/home/aldo/tweakersClone/src/venv_server/lib/python3.9/site-packages/selenium/webdriver/remote/webdriver.py", line 311, in execute
    self.error_handler.check_response(response)
  File "/home/aldo/tweakersClone/src/venv_server/lib/python3.9/site-packages/selenium/webdriver/remote/errorhandler.py", line 237, in check_response
    raise exception_class(message, screen, stacktrace)
selenium.common.exceptions.WebDriverException: Message: Process unexpectedly closed with status 1


2022-02-01 14:22:51,141 - INFO - Attempt 3 of activating geckodriver
2022-02-01 14:22:52,643 - ERROR - Geckodriver activation attempt 4 FAILED 
Traceback (most recent call last):
  File "/home/aldo/tweakersClone/src/webScraperCommon.py", line 209, in __init__
    self.driver = webdriver.Firefox(executable_path=self.pwd + self.geckodriverExe, options=self.firefox_options)
  File "/home/aldo/tweakersClone/src/venv_server/lib/python3.9/site-packages/selenium/webdriver/firefox/webdriver.py", line 154, in __init__
    RemoteWebDriver.__init__(
  File "/home/aldo/tweakersClone/src/venv_server/lib/python3.9/site-packages/selenium/webdriver/remote/webdriver.py", line 154, in __init__
    self.start_session(desired_capabilities, browser_profile)
  File "/home/aldo/tweakersClone/src/venv_server/lib/python3.9/site-packages/selenium/webdriver/remote/webdriver.py", line 243, in start_session
    response = self.execute(Command.NEW_SESSION, parameters)
  File "/home/aldo/tweakersClone/src/venv_server/lib/python3.9/site-packages/selenium/webdriver/remote/webdriver.py", line 311, in execute
    self.error_handler.check_response(response)
  File "/home/aldo/tweakersClone/src/venv_server/lib/python3.9/site-packages/selenium/webdriver/remote/errorhandler.py", line 237, in check_response
    raise exception_class(message, screen, stacktrace)
selenium.common.exceptions.WebDriverException: Message: Process unexpectedly closed with status 1


2022-02-01 14:22:52,648 - ERROR - Some error happened during scraping: Traceback (most recent call last):
  File "/home/aldo/tweakersClone/src/webScraperCommon.py", line 233, in scrapeStore
    self.driver.get(self._get_url(page))
AttributeError: 'Scrape' object has no attribute 'driver'

2022-02-01 14:27:58,087 - ERROR - SSH tunneling attempt 1 FAILED 
Traceback (most recent call last):
  File "/home/aldo/tweakersClone/src/webScraperCommon.py", line 67, in _tunnelToDatabaseServer
    tunnel.start()
  File "/home/aldo/tweakersClone/src/venv_server/lib/python3.9/site-packages/sshtunnel.py", line 1329, in start
    self._create_tunnels()
  File "/home/aldo/tweakersClone/src/venv_server/lib/python3.9/site-packages/sshtunnel.py", line 1214, in _create_tunnels
    self._connect_to_gateway()
  File "/home/aldo/tweakersClone/src/venv_server/lib/python3.9/site-packages/sshtunnel.py", line 1404, in _connect_to_gateway
    self._transport.connect(hostkey=self.ssh_host_key,
  File "/home/aldo/tweakersClone/src/venv_server/lib/python3.9/site-packages/paramiko/transport.py", line 1291, in connect
    self.start_client()
  File "/home/aldo/tweakersClone/src/venv_server/lib/python3.9/site-packages/paramiko/transport.py", line 656, in start_client
    event.wait(0.1)
  File "/usr/lib/python3.9/threading.py", line 574, in wait
    signaled = self._cond.wait(timeout)
  File "/usr/lib/python3.9/threading.py", line 321, in wait
    self._acquire_restore(saved_state)
  File "/home/aldo/tweakersClone/src/venv_server/lib/python3.9/site-packages/interruptingcow/__init__.py", line 74, in handler
    raise exception
RuntimeError

2022-02-01 14:29:43,366 - INFO - Attempt 1 of activating geckodriver
2022-02-01 14:29:44,891 - ERROR - Geckodriver activation attempt 1 FAILED 
Traceback (most recent call last):
  File "/home/aldo/tweakersClone/src/webScraperCommon.py", line 208, in __init__
    self.driver = webdriver.Firefox(executable_path=self.pwd + self.geckodriverExe, options=self.firefox_options)
  File "/home/aldo/tweakersClone/src/venv_server/lib/python3.9/site-packages/selenium/webdriver/firefox/webdriver.py", line 154, in __init__
    RemoteWebDriver.__init__(
  File "/home/aldo/tweakersClone/src/venv_server/lib/python3.9/site-packages/selenium/webdriver/remote/webdriver.py", line 154, in __init__
    self.start_session(desired_capabilities, browser_profile)
  File "/home/aldo/tweakersClone/src/venv_server/lib/python3.9/site-packages/selenium/webdriver/remote/webdriver.py", line 243, in start_session
    response = self.execute(Command.NEW_SESSION, parameters)
  File "/home/aldo/tweakersClone/src/venv_server/lib/python3.9/site-packages/selenium/webdriver/remote/webdriver.py", line 311, in execute
    self.error_handler.check_response(response)
  File "/home/aldo/tweakersClone/src/venv_server/lib/python3.9/site-packages/selenium/webdriver/remote/errorhandler.py", line 237, in check_response
    raise exception_class(message, screen, stacktrace)
selenium.common.exceptions.WebDriverException: Message: Process unexpectedly closed with status 1


2022-02-01 14:29:44,894 - INFO - Attempt 2 of activating geckodriver
2022-02-01 14:29:46,271 - ERROR - Geckodriver activation attempt 2 FAILED 
Traceback (most recent call last):
  File "/home/aldo/tweakersClone/src/webScraperCommon.py", line 208, in __init__
    self.driver = webdriver.Firefox(executable_path=self.pwd + self.geckodriverExe, options=self.firefox_options)
  File "/home/aldo/tweakersClone/src/venv_server/lib/python3.9/site-packages/selenium/webdriver/firefox/webdriver.py", line 154, in __init__
    RemoteWebDriver.__init__(
  File "/home/aldo/tweakersClone/src/venv_server/lib/python3.9/site-packages/selenium/webdriver/remote/webdriver.py", line 154, in __init__
    self.start_session(desired_capabilities, browser_profile)
  File "/home/aldo/tweakersClone/src/venv_server/lib/python3.9/site-packages/selenium/webdriver/remote/webdriver.py", line 243, in start_session
    response = self.execute(Command.NEW_SESSION, parameters)
  File "/home/aldo/tweakersClone/src/venv_server/lib/python3.9/site-packages/selenium/webdriver/remote/webdriver.py", line 311, in execute
    self.error_handler.check_response(response)
  File "/home/aldo/tweakersClone/src/venv_server/lib/python3.9/site-packages/selenium/webdriver/remote/errorhandler.py", line 237, in check_response
    raise exception_class(message, screen, stacktrace)
selenium.common.exceptions.WebDriverException: Message: Process unexpectedly closed with status 1


2022-02-01 14:29:46,277 - INFO - Attempt 3 of activating geckodriver
2022-02-01 14:29:47,649 - ERROR - Geckodriver activation attempt 3 FAILED 
Traceback (most recent call last):
  File "/home/aldo/tweakersClone/src/webScraperCommon.py", line 208, in __init__
    self.driver = webdriver.Firefox(executable_path=self.pwd + self.geckodriverExe, options=self.firefox_options)
  File "/home/aldo/tweakersClone/src/venv_server/lib/python3.9/site-packages/selenium/webdriver/firefox/webdriver.py", line 154, in __init__
    RemoteWebDriver.__init__(
  File "/home/aldo/tweakersClone/src/venv_server/lib/python3.9/site-packages/selenium/webdriver/remote/webdriver.py", line 154, in __init__
    self.start_session(desired_capabilities, browser_profile)
  File "/home/aldo/tweakersClone/src/venv_server/lib/python3.9/site-packages/selenium/webdriver/remote/webdriver.py", line 243, in start_session
    response = self.execute(Command.NEW_SESSION, parameters)
  File "/home/aldo/tweakersClone/src/venv_server/lib/python3.9/site-packages/selenium/webdriver/remote/webdriver.py", line 311, in execute
    self.error_handler.check_response(response)
  File "/home/aldo/tweakersClone/src/venv_server/lib/python3.9/site-packages/selenium/webdriver/remote/errorhandler.py", line 237, in check_response
    raise exception_class(message, screen, stacktrace)
selenium.common.exceptions.WebDriverException: Message: Process unexpectedly closed with status 1


2022-02-01 14:29:47,657 - ERROR - Max attempts to turn on geckodriver reached, traceback: 
Traceback (most recent call last):
  File "/home/aldo/tweakersClone/src/webScraperCommon.py", line 208, in __init__
    self.driver = webdriver.Firefox(executable_path=self.pwd + self.geckodriverExe, options=self.firefox_options)
  File "/home/aldo/tweakersClone/src/venv_server/lib/python3.9/site-packages/selenium/webdriver/firefox/webdriver.py", line 154, in __init__
    RemoteWebDriver.__init__(
  File "/home/aldo/tweakersClone/src/venv_server/lib/python3.9/site-packages/selenium/webdriver/remote/webdriver.py", line 154, in __init__
    self.start_session(desired_capabilities, browser_profile)
  File "/home/aldo/tweakersClone/src/venv_server/lib/python3.9/site-packages/selenium/webdriver/remote/webdriver.py", line 243, in start_session
    response = self.execute(Command.NEW_SESSION, parameters)
  File "/home/aldo/tweakersClone/src/venv_server/lib/python3.9/site-packages/selenium/webdriver/remote/webdriver.py", line 311, in execute
    self.error_handler.check_response(response)
  File "/home/aldo/tweakersClone/src/venv_server/lib/python3.9/site-packages/selenium/webdriver/remote/errorhandler.py", line 237, in check_response
    raise exception_class(message, screen, stacktrace)
selenium.common.exceptions.WebDriverException: Message: Process unexpectedly closed with status 1


2022-02-01 14:33:26,363 - INFO - Attempt 1 of activating geckodriver
2022-02-01 14:33:27,603 - ERROR - Geckodriver activation attempt 1 FAILED 
Traceback (most recent call last):
  File "/home/aldo/tweakersClone/src/webScraperCommon.py", line 208, in __init__
    self.driver = webdriver.Firefox(executable_path=self.pwd + self.geckodriverExe, options=self.firefox_options)
  File "/home/aldo/tweakersClone/src/venv_server/lib/python3.9/site-packages/selenium/webdriver/firefox/webdriver.py", line 154, in __init__
    RemoteWebDriver.__init__(
  File "/home/aldo/tweakersClone/src/venv_server/lib/python3.9/site-packages/selenium/webdriver/remote/webdriver.py", line 154, in __init__
    self.start_session(desired_capabilities, browser_profile)
  File "/home/aldo/tweakersClone/src/venv_server/lib/python3.9/site-packages/selenium/webdriver/remote/webdriver.py", line 243, in start_session
    response = self.execute(Command.NEW_SESSION, parameters)
  File "/home/aldo/tweakersClone/src/venv_server/lib/python3.9/site-packages/selenium/webdriver/remote/webdriver.py", line 311, in execute
    self.error_handler.check_response(response)
  File "/home/aldo/tweakersClone/src/venv_server/lib/python3.9/site-packages/selenium/webdriver/remote/errorhandler.py", line 237, in check_response
    raise exception_class(message, screen, stacktrace)
selenium.common.exceptions.WebDriverException: Message: Process unexpectedly closed with status 1


2022-02-01 14:33:27,605 - INFO - Attempt 2 of activating geckodriver
2022-02-01 14:33:28,743 - ERROR - Geckodriver activation attempt 2 FAILED 
Traceback (most recent call last):
  File "/home/aldo/tweakersClone/src/webScraperCommon.py", line 208, in __init__
    self.driver = webdriver.Firefox(executable_path=self.pwd + self.geckodriverExe, options=self.firefox_options)
  File "/home/aldo/tweakersClone/src/venv_server/lib/python3.9/site-packages/selenium/webdriver/firefox/webdriver.py", line 154, in __init__
    RemoteWebDriver.__init__(
  File "/home/aldo/tweakersClone/src/venv_server/lib/python3.9/site-packages/selenium/webdriver/remote/webdriver.py", line 154, in __init__
    self.start_session(desired_capabilities, browser_profile)
  File "/home/aldo/tweakersClone/src/venv_server/lib/python3.9/site-packages/selenium/webdriver/remote/webdriver.py", line 243, in start_session
    response = self.execute(Command.NEW_SESSION, parameters)
  File "/home/aldo/tweakersClone/src/venv_server/lib/python3.9/site-packages/selenium/webdriver/remote/webdriver.py", line 311, in execute
    self.error_handler.check_response(response)
  File "/home/aldo/tweakersClone/src/venv_server/lib/python3.9/site-packages/selenium/webdriver/remote/errorhandler.py", line 237, in check_response
    raise exception_class(message, screen, stacktrace)
selenium.common.exceptions.WebDriverException: Message: Process unexpectedly closed with status 1


2022-02-01 14:33:28,745 - INFO - Attempt 3 of activating geckodriver
2022-02-01 14:33:29,880 - ERROR - Geckodriver activation attempt 3 FAILED 
Traceback (most recent call last):
  File "/home/aldo/tweakersClone/src/webScraperCommon.py", line 208, in __init__
    self.driver = webdriver.Firefox(executable_path=self.pwd + self.geckodriverExe, options=self.firefox_options)
  File "/home/aldo/tweakersClone/src/venv_server/lib/python3.9/site-packages/selenium/webdriver/firefox/webdriver.py", line 154, in __init__
    RemoteWebDriver.__init__(
  File "/home/aldo/tweakersClone/src/venv_server/lib/python3.9/site-packages/selenium/webdriver/remote/webdriver.py", line 154, in __init__
    self.start_session(desired_capabilities, browser_profile)
  File "/home/aldo/tweakersClone/src/venv_server/lib/python3.9/site-packages/selenium/webdriver/remote/webdriver.py", line 243, in start_session
    response = self.execute(Command.NEW_SESSION, parameters)
  File "/home/aldo/tweakersClone/src/venv_server/lib/python3.9/site-packages/selenium/webdriver/remote/webdriver.py", line 311, in execute
    self.error_handler.check_response(response)
  File "/home/aldo/tweakersClone/src/venv_server/lib/python3.9/site-packages/selenium/webdriver/remote/errorhandler.py", line 237, in check_response
    raise exception_class(message, screen, stacktrace)
selenium.common.exceptions.WebDriverException: Message: Process unexpectedly closed with status 1


2022-02-01 14:33:29,882 - ERROR - Max attempts to turn on geckodriver reached, traceback: 
Traceback (most recent call last):
  File "/home/aldo/tweakersClone/src/webScraperCommon.py", line 208, in __init__
    self.driver = webdriver.Firefox(executable_path=self.pwd + self.geckodriverExe, options=self.firefox_options)
  File "/home/aldo/tweakersClone/src/venv_server/lib/python3.9/site-packages/selenium/webdriver/firefox/webdriver.py", line 154, in __init__
    RemoteWebDriver.__init__(
  File "/home/aldo/tweakersClone/src/venv_server/lib/python3.9/site-packages/selenium/webdriver/remote/webdriver.py", line 154, in __init__
    self.start_session(desired_capabilities, browser_profile)
  File "/home/aldo/tweakersClone/src/venv_server/lib/python3.9/site-packages/selenium/webdriver/remote/webdriver.py", line 243, in start_session
    response = self.execute(Command.NEW_SESSION, parameters)
  File "/home/aldo/tweakersClone/src/venv_server/lib/python3.9/site-packages/selenium/webdriver/remote/webdriver.py", line 311, in execute
    self.error_handler.check_response(response)
  File "/home/aldo/tweakersClone/src/venv_server/lib/python3.9/site-packages/selenium/webdriver/remote/errorhandler.py", line 237, in check_response
    raise exception_class(message, screen, stacktrace)
selenium.common.exceptions.WebDriverException: Message: Process unexpectedly closed with status 1


2022-02-01 14:46:48,048 - INFO - Attempt 1 of activating geckodriver
2022-02-01 14:46:49,408 - ERROR - Geckodriver activation attempt 1 FAILED 
Traceback (most recent call last):
  File "/home/aldo/tweakersClone/src/webScraperCommon.py", line 208, in __init__
    self.driver = webdriver.Firefox(executable_path=self.pwd + self.geckodriverExe, options=self.firefox_options)
  File "/home/aldo/tweakersClone/src/venv_server/lib/python3.9/site-packages/selenium/webdriver/firefox/webdriver.py", line 154, in __init__
    RemoteWebDriver.__init__(
  File "/home/aldo/tweakersClone/src/venv_server/lib/python3.9/site-packages/selenium/webdriver/remote/webdriver.py", line 154, in __init__
    self.start_session(desired_capabilities, browser_profile)
  File "/home/aldo/tweakersClone/src/venv_server/lib/python3.9/site-packages/selenium/webdriver/remote/webdriver.py", line 243, in start_session
    response = self.execute(Command.NEW_SESSION, parameters)
  File "/home/aldo/tweakersClone/src/venv_server/lib/python3.9/site-packages/selenium/webdriver/remote/webdriver.py", line 311, in execute
    self.error_handler.check_response(response)
  File "/home/aldo/tweakersClone/src/venv_server/lib/python3.9/site-packages/selenium/webdriver/remote/errorhandler.py", line 237, in check_response
    raise exception_class(message, screen, stacktrace)
selenium.common.exceptions.WebDriverException: Message: Process unexpectedly closed with status 1


2022-02-01 14:46:49,411 - INFO - Attempt 2 of activating geckodriver
2022-02-01 14:46:50,556 - ERROR - Geckodriver activation attempt 2 FAILED 
Traceback (most recent call last):
  File "/home/aldo/tweakersClone/src/webScraperCommon.py", line 208, in __init__
    self.driver = webdriver.Firefox(executable_path=self.pwd + self.geckodriverExe, options=self.firefox_options)
  File "/home/aldo/tweakersClone/src/venv_server/lib/python3.9/site-packages/selenium/webdriver/firefox/webdriver.py", line 154, in __init__
    RemoteWebDriver.__init__(
  File "/home/aldo/tweakersClone/src/venv_server/lib/python3.9/site-packages/selenium/webdriver/remote/webdriver.py", line 154, in __init__
    self.start_session(desired_capabilities, browser_profile)
  File "/home/aldo/tweakersClone/src/venv_server/lib/python3.9/site-packages/selenium/webdriver/remote/webdriver.py", line 243, in start_session
    response = self.execute(Command.NEW_SESSION, parameters)
  File "/home/aldo/tweakersClone/src/venv_server/lib/python3.9/site-packages/selenium/webdriver/remote/webdriver.py", line 311, in execute
    self.error_handler.check_response(response)
  File "/home/aldo/tweakersClone/src/venv_server/lib/python3.9/site-packages/selenium/webdriver/remote/errorhandler.py", line 237, in check_response
    raise exception_class(message, screen, stacktrace)
selenium.common.exceptions.WebDriverException: Message: Process unexpectedly closed with status 1


2022-02-01 14:46:50,560 - INFO - Attempt 3 of activating geckodriver
2022-02-01 14:46:51,703 - ERROR - Geckodriver activation attempt 3 FAILED 
Traceback (most recent call last):
  File "/home/aldo/tweakersClone/src/webScraperCommon.py", line 208, in __init__
    self.driver = webdriver.Firefox(executable_path=self.pwd + self.geckodriverExe, options=self.firefox_options)
  File "/home/aldo/tweakersClone/src/venv_server/lib/python3.9/site-packages/selenium/webdriver/firefox/webdriver.py", line 154, in __init__
    RemoteWebDriver.__init__(
  File "/home/aldo/tweakersClone/src/venv_server/lib/python3.9/site-packages/selenium/webdriver/remote/webdriver.py", line 154, in __init__
    self.start_session(desired_capabilities, browser_profile)
  File "/home/aldo/tweakersClone/src/venv_server/lib/python3.9/site-packages/selenium/webdriver/remote/webdriver.py", line 243, in start_session
    response = self.execute(Command.NEW_SESSION, parameters)
  File "/home/aldo/tweakersClone/src/venv_server/lib/python3.9/site-packages/selenium/webdriver/remote/webdriver.py", line 311, in execute
    self.error_handler.check_response(response)
  File "/home/aldo/tweakersClone/src/venv_server/lib/python3.9/site-packages/selenium/webdriver/remote/errorhandler.py", line 237, in check_response
    raise exception_class(message, screen, stacktrace)
selenium.common.exceptions.WebDriverException: Message: Process unexpectedly closed with status 1


2022-02-01 14:46:51,713 - ERROR - Max attempts to turn on geckodriver reached, traceback: 
Traceback (most recent call last):
  File "/home/aldo/tweakersClone/src/webScraperCommon.py", line 208, in __init__
    self.driver = webdriver.Firefox(executable_path=self.pwd + self.geckodriverExe, options=self.firefox_options)
  File "/home/aldo/tweakersClone/src/venv_server/lib/python3.9/site-packages/selenium/webdriver/firefox/webdriver.py", line 154, in __init__
    RemoteWebDriver.__init__(
  File "/home/aldo/tweakersClone/src/venv_server/lib/python3.9/site-packages/selenium/webdriver/remote/webdriver.py", line 154, in __init__
    self.start_session(desired_capabilities, browser_profile)
  File "/home/aldo/tweakersClone/src/venv_server/lib/python3.9/site-packages/selenium/webdriver/remote/webdriver.py", line 243, in start_session
    response = self.execute(Command.NEW_SESSION, parameters)
  File "/home/aldo/tweakersClone/src/venv_server/lib/python3.9/site-packages/selenium/webdriver/remote/webdriver.py", line 311, in execute
    self.error_handler.check_response(response)
  File "/home/aldo/tweakersClone/src/venv_server/lib/python3.9/site-packages/selenium/webdriver/remote/errorhandler.py", line 237, in check_response
    raise exception_class(message, screen, stacktrace)
selenium.common.exceptions.WebDriverException: Message: Process unexpectedly closed with status 1


2022-02-01 14:47:20,915 - INFO - Attempt 1 of activating geckodriver
2022-02-01 14:47:22,043 - ERROR - Geckodriver activation attempt 1 FAILED 
Traceback (most recent call last):
  File "/home/aldo/tweakersClone/src/webScraperCommon.py", line 208, in __init__
    self.driver = webdriver.Firefox(executable_path=self.pwd + self.geckodriverExe, options=self.firefox_options)
  File "/home/aldo/tweakersClone/src/venv_server/lib/python3.9/site-packages/selenium/webdriver/firefox/webdriver.py", line 154, in __init__
    RemoteWebDriver.__init__(
  File "/home/aldo/tweakersClone/src/venv_server/lib/python3.9/site-packages/selenium/webdriver/remote/webdriver.py", line 154, in __init__
    self.start_session(desired_capabilities, browser_profile)
  File "/home/aldo/tweakersClone/src/venv_server/lib/python3.9/site-packages/selenium/webdriver/remote/webdriver.py", line 243, in start_session
    response = self.execute(Command.NEW_SESSION, parameters)
  File "/home/aldo/tweakersClone/src/venv_server/lib/python3.9/site-packages/selenium/webdriver/remote/webdriver.py", line 311, in execute
    self.error_handler.check_response(response)
  File "/home/aldo/tweakersClone/src/venv_server/lib/python3.9/site-packages/selenium/webdriver/remote/errorhandler.py", line 237, in check_response
    raise exception_class(message, screen, stacktrace)
selenium.common.exceptions.WebDriverException: Message: Process unexpectedly closed with status 1


2022-02-01 14:47:22,045 - INFO - Attempt 2 of activating geckodriver
2022-02-01 14:47:23,173 - ERROR - Geckodriver activation attempt 2 FAILED 
Traceback (most recent call last):
  File "/home/aldo/tweakersClone/src/webScraperCommon.py", line 208, in __init__
    self.driver = webdriver.Firefox(executable_path=self.pwd + self.geckodriverExe, options=self.firefox_options)
  File "/home/aldo/tweakersClone/src/venv_server/lib/python3.9/site-packages/selenium/webdriver/firefox/webdriver.py", line 154, in __init__
    RemoteWebDriver.__init__(
  File "/home/aldo/tweakersClone/src/venv_server/lib/python3.9/site-packages/selenium/webdriver/remote/webdriver.py", line 154, in __init__
    self.start_session(desired_capabilities, browser_profile)
  File "/home/aldo/tweakersClone/src/venv_server/lib/python3.9/site-packages/selenium/webdriver/remote/webdriver.py", line 243, in start_session
    response = self.execute(Command.NEW_SESSION, parameters)
  File "/home/aldo/tweakersClone/src/venv_server/lib/python3.9/site-packages/selenium/webdriver/remote/webdriver.py", line 311, in execute
    self.error_handler.check_response(response)
  File "/home/aldo/tweakersClone/src/venv_server/lib/python3.9/site-packages/selenium/webdriver/remote/errorhandler.py", line 237, in check_response
    raise exception_class(message, screen, stacktrace)
selenium.common.exceptions.WebDriverException: Message: Process unexpectedly closed with status 1


2022-02-01 14:47:23,175 - INFO - Attempt 3 of activating geckodriver
2022-02-01 14:47:24,301 - ERROR - Geckodriver activation attempt 3 FAILED 
Traceback (most recent call last):
  File "/home/aldo/tweakersClone/src/webScraperCommon.py", line 208, in __init__
    self.driver = webdriver.Firefox(executable_path=self.pwd + self.geckodriverExe, options=self.firefox_options)
  File "/home/aldo/tweakersClone/src/venv_server/lib/python3.9/site-packages/selenium/webdriver/firefox/webdriver.py", line 154, in __init__
    RemoteWebDriver.__init__(
  File "/home/aldo/tweakersClone/src/venv_server/lib/python3.9/site-packages/selenium/webdriver/remote/webdriver.py", line 154, in __init__
    self.start_session(desired_capabilities, browser_profile)
  File "/home/aldo/tweakersClone/src/venv_server/lib/python3.9/site-packages/selenium/webdriver/remote/webdriver.py", line 243, in start_session
    response = self.execute(Command.NEW_SESSION, parameters)
  File "/home/aldo/tweakersClone/src/venv_server/lib/python3.9/site-packages/selenium/webdriver/remote/webdriver.py", line 311, in execute
    self.error_handler.check_response(response)
  File "/home/aldo/tweakersClone/src/venv_server/lib/python3.9/site-packages/selenium/webdriver/remote/errorhandler.py", line 237, in check_response
    raise exception_class(message, screen, stacktrace)
selenium.common.exceptions.WebDriverException: Message: Process unexpectedly closed with status 1


2022-02-01 14:47:24,303 - ERROR - Max attempts to turn on geckodriver reached, traceback: 
Traceback (most recent call last):
  File "/home/aldo/tweakersClone/src/webScraperCommon.py", line 208, in __init__
    self.driver = webdriver.Firefox(executable_path=self.pwd + self.geckodriverExe, options=self.firefox_options)
  File "/home/aldo/tweakersClone/src/venv_server/lib/python3.9/site-packages/selenium/webdriver/firefox/webdriver.py", line 154, in __init__
    RemoteWebDriver.__init__(
  File "/home/aldo/tweakersClone/src/venv_server/lib/python3.9/site-packages/selenium/webdriver/remote/webdriver.py", line 154, in __init__
    self.start_session(desired_capabilities, browser_profile)
  File "/home/aldo/tweakersClone/src/venv_server/lib/python3.9/site-packages/selenium/webdriver/remote/webdriver.py", line 243, in start_session
    response = self.execute(Command.NEW_SESSION, parameters)
  File "/home/aldo/tweakersClone/src/venv_server/lib/python3.9/site-packages/selenium/webdriver/remote/webdriver.py", line 311, in execute
    self.error_handler.check_response(response)
  File "/home/aldo/tweakersClone/src/venv_server/lib/python3.9/site-packages/selenium/webdriver/remote/errorhandler.py", line 237, in check_response
    raise exception_class(message, screen, stacktrace)
selenium.common.exceptions.WebDriverException: Message: Process unexpectedly closed with status 1


2022-02-01 14:49:51,109 - INFO - Attempt 1 of activating geckodriver
2022-02-01 14:49:59,271 - ERROR - Geckodriver activation attempt 1 FAILED 
Traceback (most recent call last):
  File "/home/aldo/tweakersClone/src/webScraperCommon.py", line 208, in __init__
    self.driver = webdriver.Firefox(executable_path=self.pwd + self.geckodriverExe, options=self.firefox_options)
  File "/home/aldo/tweakersClone/src/venv_server/lib/python3.9/site-packages/selenium/webdriver/firefox/webdriver.py", line 154, in __init__
    RemoteWebDriver.__init__(
  File "/home/aldo/tweakersClone/src/venv_server/lib/python3.9/site-packages/selenium/webdriver/remote/webdriver.py", line 154, in __init__
    self.start_session(desired_capabilities, browser_profile)
  File "/home/aldo/tweakersClone/src/venv_server/lib/python3.9/site-packages/selenium/webdriver/remote/webdriver.py", line 243, in start_session
    response = self.execute(Command.NEW_SESSION, parameters)
  File "/home/aldo/tweakersClone/src/venv_server/lib/python3.9/site-packages/selenium/webdriver/remote/webdriver.py", line 309, in execute
    response = self.command_executor.execute(driver_command, params)
  File "/home/aldo/tweakersClone/src/venv_server/lib/python3.9/site-packages/selenium/webdriver/remote/remote_connection.py", line 460, in execute
    return self._request(command_info[0], url, body=data)
  File "/home/aldo/tweakersClone/src/venv_server/lib/python3.9/site-packages/selenium/webdriver/remote/remote_connection.py", line 484, in _request
    resp = self._conn.getresponse()
  File "/usr/lib/python3.9/http/client.py", line 1349, in getresponse
    response.begin()
  File "/usr/lib/python3.9/http/client.py", line 316, in begin
    version, status, reason = self._read_status()
  File "/usr/lib/python3.9/http/client.py", line 277, in _read_status
    line = str(self.fp.readline(_MAXLINE + 1), "iso-8859-1")
  File "/usr/lib/python3.9/socket.py", line 704, in readinto
    return self._sock.recv_into(b)
  File "/home/aldo/tweakersClone/src/venv_server/lib/python3.9/site-packages/interruptingcow/__init__.py", line 74, in handler
    raise exception
RuntimeError

2022-02-01 14:49:59,278 - INFO - Attempt 2 of activating geckodriver
2022-02-01 14:50:07,417 - ERROR - Geckodriver activation attempt 2 FAILED 
Traceback (most recent call last):
  File "/home/aldo/tweakersClone/src/webScraperCommon.py", line 208, in __init__
    self.driver = webdriver.Firefox(executable_path=self.pwd + self.geckodriverExe, options=self.firefox_options)
  File "/home/aldo/tweakersClone/src/venv_server/lib/python3.9/site-packages/selenium/webdriver/firefox/webdriver.py", line 154, in __init__
    RemoteWebDriver.__init__(
  File "/home/aldo/tweakersClone/src/venv_server/lib/python3.9/site-packages/selenium/webdriver/remote/webdriver.py", line 154, in __init__
    self.start_session(desired_capabilities, browser_profile)
  File "/home/aldo/tweakersClone/src/venv_server/lib/python3.9/site-packages/selenium/webdriver/remote/webdriver.py", line 243, in start_session
    response = self.execute(Command.NEW_SESSION, parameters)
  File "/home/aldo/tweakersClone/src/venv_server/lib/python3.9/site-packages/selenium/webdriver/remote/webdriver.py", line 309, in execute
    response = self.command_executor.execute(driver_command, params)
  File "/home/aldo/tweakersClone/src/venv_server/lib/python3.9/site-packages/selenium/webdriver/remote/remote_connection.py", line 460, in execute
    return self._request(command_info[0], url, body=data)
  File "/home/aldo/tweakersClone/src/venv_server/lib/python3.9/site-packages/selenium/webdriver/remote/remote_connection.py", line 484, in _request
    resp = self._conn.getresponse()
  File "/usr/lib/python3.9/http/client.py", line 1349, in getresponse
    response.begin()
  File "/usr/lib/python3.9/http/client.py", line 316, in begin
    version, status, reason = self._read_status()
  File "/usr/lib/python3.9/http/client.py", line 277, in _read_status
    line = str(self.fp.readline(_MAXLINE + 1), "iso-8859-1")
  File "/usr/lib/python3.9/socket.py", line 704, in readinto
    return self._sock.recv_into(b)
  File "/home/aldo/tweakersClone/src/venv_server/lib/python3.9/site-packages/interruptingcow/__init__.py", line 74, in handler
    raise exception
RuntimeError

2022-02-01 14:50:07,428 - INFO - Attempt 3 of activating geckodriver
2022-02-01 14:50:15,702 - ERROR - Geckodriver activation attempt 3 FAILED 
Traceback (most recent call last):
  File "/home/aldo/tweakersClone/src/webScraperCommon.py", line 208, in __init__
    self.driver = webdriver.Firefox(executable_path=self.pwd + self.geckodriverExe, options=self.firefox_options)
  File "/home/aldo/tweakersClone/src/venv_server/lib/python3.9/site-packages/selenium/webdriver/firefox/webdriver.py", line 154, in __init__
    RemoteWebDriver.__init__(
  File "/home/aldo/tweakersClone/src/venv_server/lib/python3.9/site-packages/selenium/webdriver/remote/webdriver.py", line 154, in __init__
    self.start_session(desired_capabilities, browser_profile)
  File "/home/aldo/tweakersClone/src/venv_server/lib/python3.9/site-packages/selenium/webdriver/remote/webdriver.py", line 243, in start_session
    response = self.execute(Command.NEW_SESSION, parameters)
  File "/home/aldo/tweakersClone/src/venv_server/lib/python3.9/site-packages/selenium/webdriver/remote/webdriver.py", line 309, in execute
    response = self.command_executor.execute(driver_command, params)
  File "/home/aldo/tweakersClone/src/venv_server/lib/python3.9/site-packages/selenium/webdriver/remote/remote_connection.py", line 460, in execute
    return self._request(command_info[0], url, body=data)
  File "/home/aldo/tweakersClone/src/venv_server/lib/python3.9/site-packages/selenium/webdriver/remote/remote_connection.py", line 484, in _request
    resp = self._conn.getresponse()
  File "/usr/lib/python3.9/http/client.py", line 1349, in getresponse
    response.begin()
  File "/usr/lib/python3.9/http/client.py", line 316, in begin
    version, status, reason = self._read_status()
  File "/usr/lib/python3.9/http/client.py", line 277, in _read_status
    line = str(self.fp.readline(_MAXLINE + 1), "iso-8859-1")
  File "/usr/lib/python3.9/socket.py", line 704, in readinto
    return self._sock.recv_into(b)
  File "/home/aldo/tweakersClone/src/venv_server/lib/python3.9/site-packages/interruptingcow/__init__.py", line 74, in handler
    raise exception
RuntimeError

2022-02-01 14:50:15,713 - ERROR - Max attempts to turn on geckodriver reached, traceback: 
Traceback (most recent call last):
  File "/home/aldo/tweakersClone/src/webScraperCommon.py", line 208, in __init__
    self.driver = webdriver.Firefox(executable_path=self.pwd + self.geckodriverExe, options=self.firefox_options)
  File "/home/aldo/tweakersClone/src/venv_server/lib/python3.9/site-packages/selenium/webdriver/firefox/webdriver.py", line 154, in __init__
    RemoteWebDriver.__init__(
  File "/home/aldo/tweakersClone/src/venv_server/lib/python3.9/site-packages/selenium/webdriver/remote/webdriver.py", line 154, in __init__
    self.start_session(desired_capabilities, browser_profile)
  File "/home/aldo/tweakersClone/src/venv_server/lib/python3.9/site-packages/selenium/webdriver/remote/webdriver.py", line 243, in start_session
    response = self.execute(Command.NEW_SESSION, parameters)
  File "/home/aldo/tweakersClone/src/venv_server/lib/python3.9/site-packages/selenium/webdriver/remote/webdriver.py", line 309, in execute
    response = self.command_executor.execute(driver_command, params)
  File "/home/aldo/tweakersClone/src/venv_server/lib/python3.9/site-packages/selenium/webdriver/remote/remote_connection.py", line 460, in execute
    return self._request(command_info[0], url, body=data)
  File "/home/aldo/tweakersClone/src/venv_server/lib/python3.9/site-packages/selenium/webdriver/remote/remote_connection.py", line 484, in _request
    resp = self._conn.getresponse()
  File "/usr/lib/python3.9/http/client.py", line 1349, in getresponse
    response.begin()
  File "/usr/lib/python3.9/http/client.py", line 316, in begin
    version, status, reason = self._read_status()
  File "/usr/lib/python3.9/http/client.py", line 277, in _read_status
    line = str(self.fp.readline(_MAXLINE + 1), "iso-8859-1")
  File "/usr/lib/python3.9/socket.py", line 704, in readinto
    return self._sock.recv_into(b)
  File "/home/aldo/tweakersClone/src/venv_server/lib/python3.9/site-packages/interruptingcow/__init__.py", line 74, in handler
    raise exception
RuntimeError

2022-02-01 14:54:22,281 - INFO - Attempt 1 of activating geckodriver
2022-02-01 14:54:28,353 - INFO - geckodriver successfully activated
2022-02-01 18:08:34,047 - INFO - Attempt 1 of activating geckodriver
2022-02-01 18:08:40,404 - INFO - geckodriver successfully activated
2022-02-01 18:08:52,290 - INFO - Attempt 1 of activating geckodriver
2022-02-01 18:08:57,786 - INFO - geckodriver successfully activated
2022-02-01 18:16:15,866 - INFO - Attempt 1 of activating geckodriver
2022-02-01 18:16:21,373 - INFO - geckodriver successfully activated
2022-02-01 18:16:40,542 - INFO - Attempt 1 of activating geckodriver
2022-02-01 18:16:45,566 - INFO - geckodriver successfully activated
2022-02-02 04:06:44,307 - ERROR - Credentials of database not available, traceback: 
Traceback (most recent call last):
  File "/home/aldo/tweakersClone/src/coolblueScraper.py", line 46, in main
    username = os.environ["tweakersCloneUsername"]
  File "/usr/lib/python3.9/os.py", line 679, in __getitem__
    raise KeyError(key) from None
KeyError: 'tweakersCloneUsername'

2022-02-02 10:53:14,305 - INFO - Attempt 1 of activating geckodriver
2022-02-02 10:53:20,408 - INFO - geckodriver successfully activated
2022-02-02 10:53:33,783 - INFO - Attempt 1 of activating geckodriver
2022-02-02 10:53:39,960 - INFO - geckodriver successfully activated
2022-02-02 11:04:12,549 - INFO - Attempt 1 of activating geckodriver
2022-02-02 11:04:19,818 - INFO - geckodriver successfully activated
2022-02-02 11:04:27,713 - INFO - Attempt 1 of activating geckodriver
2022-02-02 11:04:33,935 - INFO - geckodriver successfully activated
2022-02-02 11:10:26,213 - INFO - Attempt 1 of activating geckodriver
2022-02-02 11:10:33,262 - INFO - geckodriver successfully activated
2022-02-02 11:10:47,037 - INFO - Attempt 1 of activating geckodriver
2022-02-02 11:10:53,155 - INFO - geckodriver successfully activated
2022-02-02 13:22:26,125 - INFO - Attempt 1 of activating geckodriver
2022-02-02 13:22:33,432 - INFO - geckodriver successfully activated
2022-02-02 13:22:41,953 - INFO - Attempt 1 of activating geckodriver
2022-02-02 13:22:47,657 - INFO - geckodriver successfully activated
2022-02-02 13:22:57,985 - INFO - Attempt 1 of activating geckodriver
2022-02-02 13:23:04,482 - INFO - geckodriver successfully activated
2022-02-02 13:23:10,161 - INFO - Attempt 1 of activating geckodriver
2022-02-02 13:23:16,297 - INFO - geckodriver successfully activated
2022-02-02 13:23:23,457 - INFO - Attempt 1 of activating geckodriver
2022-02-02 13:23:29,753 - INFO - geckodriver successfully activated
2022-02-02 14:39:34,161 - INFO - Attempt 1 of activating geckodriver
2022-02-02 14:39:40,841 - INFO - geckodriver successfully activated
2022-02-02 14:39:49,822 - INFO - Attempt 1 of activating geckodriver
2022-02-02 14:39:55,541 - INFO - geckodriver successfully activated
2022-02-02 14:40:06,826 - INFO - Attempt 1 of activating geckodriver
2022-02-02 14:40:13,027 - INFO - geckodriver successfully activated
2022-02-02 14:40:23,843 - INFO - Attempt 1 of activating geckodriver
2022-02-02 14:40:29,859 - INFO - geckodriver successfully activated
2022-02-02 14:40:38,934 - INFO - Attempt 1 of activating geckodriver
2022-02-02 14:40:45,402 - INFO - geckodriver successfully activated
2022-02-02 15:10:14,621 - INFO - Attempt 1 of activating geckodriver
2022-02-02 15:10:20,433 - INFO - geckodriver successfully activated
2022-02-02 15:10:34,568 - INFO - Attempt 1 of activating geckodriver
2022-02-02 15:10:40,442 - INFO - geckodriver successfully activated
2022-02-02 15:10:46,462 - INFO - Attempt 1 of activating geckodriver
2022-02-02 15:10:52,192 - INFO - geckodriver successfully activated
2022-02-02 15:10:59,996 - INFO - Attempt 1 of activating geckodriver
2022-02-02 15:11:06,217 - INFO - geckodriver successfully activated
2022-02-02 15:11:12,711 - INFO - Attempt 1 of activating geckodriver
2022-02-02 15:11:18,712 - INFO - geckodriver successfully activated
2022-02-03 03:10:30,521 - INFO - Attempt 1 of activating geckodriver
2022-02-03 03:10:35,958 - INFO - geckodriver successfully activated
2022-02-03 03:10:43,528 - INFO - Attempt 1 of activating geckodriver
2022-02-03 03:10:48,450 - INFO - geckodriver successfully activated
2022-02-03 03:10:54,743 - INFO - Attempt 1 of activating geckodriver
2022-02-03 03:11:00,793 - INFO - geckodriver successfully activated
2022-02-03 03:11:09,511 - INFO - Attempt 1 of activating geckodriver
2022-02-03 03:11:15,498 - INFO - geckodriver successfully activated
2022-02-03 03:11:22,414 - INFO - Attempt 1 of activating geckodriver
2022-02-03 03:11:27,523 - INFO - geckodriver successfully activated
2022-02-03 09:33:07,353 - INFO - No message
2022-02-03 09:33:44,929 - INFO - No message
2022-02-03 09:36:41,419 - INFO - No message
2022-02-03 09:38:14,293 - INFO - No message
2022-02-03 09:47:43,647 - INFO - No message
2022-02-03 09:48:33,172 - INFO - No message
2022-02-06 03:04:12,852 - INFO - Attempt 1 of activating geckodriver
2022-02-06 03:04:21,034 - ERROR - Geckodriver activation attempt 1 FAILED 
Traceback (most recent call last):
  File "/home/aldo/tweakersClone/src/webScraperCommon.py", line 258, in __init__
    self.driver = webdriver.Firefox(executable_path=self.pwd + self.geckodriverExe, options=self.firefox_options)
  File "/home/aldo/tweakersClone/src/venv_server/lib/python3.9/site-packages/selenium/webdriver/firefox/webdriver.py", line 154, in __init__
    RemoteWebDriver.__init__(
  File "/home/aldo/tweakersClone/src/venv_server/lib/python3.9/site-packages/selenium/webdriver/remote/webdriver.py", line 154, in __init__
    self.start_session(desired_capabilities, browser_profile)
  File "/home/aldo/tweakersClone/src/venv_server/lib/python3.9/site-packages/selenium/webdriver/remote/webdriver.py", line 243, in start_session
    response = self.execute(Command.NEW_SESSION, parameters)
  File "/home/aldo/tweakersClone/src/venv_server/lib/python3.9/site-packages/selenium/webdriver/remote/webdriver.py", line 309, in execute
    response = self.command_executor.execute(driver_command, params)
  File "/home/aldo/tweakersClone/src/venv_server/lib/python3.9/site-packages/selenium/webdriver/remote/remote_connection.py", line 460, in execute
    return self._request(command_info[0], url, body=data)
  File "/home/aldo/tweakersClone/src/venv_server/lib/python3.9/site-packages/selenium/webdriver/remote/remote_connection.py", line 484, in _request
    resp = self._conn.getresponse()
  File "/usr/lib/python3.9/http/client.py", line 1349, in getresponse
    response.begin()
  File "/usr/lib/python3.9/http/client.py", line 316, in begin
    version, status, reason = self._read_status()
  File "/usr/lib/python3.9/http/client.py", line 277, in _read_status
    line = str(self.fp.readline(_MAXLINE + 1), "iso-8859-1")
  File "/usr/lib/python3.9/socket.py", line 704, in readinto
    return self._sock.recv_into(b)
  File "/home/aldo/tweakersClone/src/venv_server/lib/python3.9/site-packages/interruptingcow/__init__.py", line 74, in handler
    raise exception
RuntimeError

2022-02-06 03:04:21,038 - INFO - Attempt 2 of activating geckodriver
2022-02-06 03:04:29,199 - ERROR - Geckodriver activation attempt 2 FAILED 
Traceback (most recent call last):
  File "/home/aldo/tweakersClone/src/webScraperCommon.py", line 258, in __init__
    self.driver = webdriver.Firefox(executable_path=self.pwd + self.geckodriverExe, options=self.firefox_options)
  File "/home/aldo/tweakersClone/src/venv_server/lib/python3.9/site-packages/selenium/webdriver/firefox/webdriver.py", line 154, in __init__
    RemoteWebDriver.__init__(
  File "/home/aldo/tweakersClone/src/venv_server/lib/python3.9/site-packages/selenium/webdriver/remote/webdriver.py", line 154, in __init__
    self.start_session(desired_capabilities, browser_profile)
  File "/home/aldo/tweakersClone/src/venv_server/lib/python3.9/site-packages/selenium/webdriver/remote/webdriver.py", line 243, in start_session
    response = self.execute(Command.NEW_SESSION, parameters)
  File "/home/aldo/tweakersClone/src/venv_server/lib/python3.9/site-packages/selenium/webdriver/remote/webdriver.py", line 309, in execute
    response = self.command_executor.execute(driver_command, params)
  File "/home/aldo/tweakersClone/src/venv_server/lib/python3.9/site-packages/selenium/webdriver/remote/remote_connection.py", line 460, in execute
    return self._request(command_info[0], url, body=data)
  File "/home/aldo/tweakersClone/src/venv_server/lib/python3.9/site-packages/selenium/webdriver/remote/remote_connection.py", line 484, in _request
    resp = self._conn.getresponse()
  File "/usr/lib/python3.9/http/client.py", line 1349, in getresponse
    response.begin()
  File "/usr/lib/python3.9/http/client.py", line 316, in begin
    version, status, reason = self._read_status()
  File "/usr/lib/python3.9/http/client.py", line 277, in _read_status
    line = str(self.fp.readline(_MAXLINE + 1), "iso-8859-1")
  File "/usr/lib/python3.9/socket.py", line 704, in readinto
    return self._sock.recv_into(b)
  File "/home/aldo/tweakersClone/src/venv_server/lib/python3.9/site-packages/interruptingcow/__init__.py", line 74, in handler
    raise exception
RuntimeError

2022-02-06 03:04:29,203 - INFO - Attempt 3 of activating geckodriver
2022-02-06 03:04:37,323 - ERROR - Geckodriver activation attempt 3 FAILED 
Traceback (most recent call last):
  File "/home/aldo/tweakersClone/src/webScraperCommon.py", line 258, in __init__
    self.driver = webdriver.Firefox(executable_path=self.pwd + self.geckodriverExe, options=self.firefox_options)
  File "/home/aldo/tweakersClone/src/venv_server/lib/python3.9/site-packages/selenium/webdriver/firefox/webdriver.py", line 154, in __init__
    RemoteWebDriver.__init__(
  File "/home/aldo/tweakersClone/src/venv_server/lib/python3.9/site-packages/selenium/webdriver/remote/webdriver.py", line 154, in __init__
    self.start_session(desired_capabilities, browser_profile)
  File "/home/aldo/tweakersClone/src/venv_server/lib/python3.9/site-packages/selenium/webdriver/remote/webdriver.py", line 243, in start_session
    response = self.execute(Command.NEW_SESSION, parameters)
  File "/home/aldo/tweakersClone/src/venv_server/lib/python3.9/site-packages/selenium/webdriver/remote/webdriver.py", line 309, in execute
    response = self.command_executor.execute(driver_command, params)
  File "/home/aldo/tweakersClone/src/venv_server/lib/python3.9/site-packages/selenium/webdriver/remote/remote_connection.py", line 460, in execute
    return self._request(command_info[0], url, body=data)
  File "/home/aldo/tweakersClone/src/venv_server/lib/python3.9/site-packages/selenium/webdriver/remote/remote_connection.py", line 484, in _request
    resp = self._conn.getresponse()
  File "/usr/lib/python3.9/http/client.py", line 1349, in getresponse
    response.begin()
  File "/usr/lib/python3.9/http/client.py", line 316, in begin
    version, status, reason = self._read_status()
  File "/usr/lib/python3.9/http/client.py", line 277, in _read_status
    line = str(self.fp.readline(_MAXLINE + 1), "iso-8859-1")
  File "/usr/lib/python3.9/socket.py", line 704, in readinto
    return self._sock.recv_into(b)
  File "/home/aldo/tweakersClone/src/venv_server/lib/python3.9/site-packages/interruptingcow/__init__.py", line 74, in handler
    raise exception
RuntimeError

2022-02-06 03:04:37,329 - ERROR - Max attempts to turn on geckodriver reached, traceback: 
Traceback (most recent call last):
  File "/home/aldo/tweakersClone/src/webScraperCommon.py", line 258, in __init__
    self.driver = webdriver.Firefox(executable_path=self.pwd + self.geckodriverExe, options=self.firefox_options)
  File "/home/aldo/tweakersClone/src/venv_server/lib/python3.9/site-packages/selenium/webdriver/firefox/webdriver.py", line 154, in __init__
    RemoteWebDriver.__init__(
  File "/home/aldo/tweakersClone/src/venv_server/lib/python3.9/site-packages/selenium/webdriver/remote/webdriver.py", line 154, in __init__
    self.start_session(desired_capabilities, browser_profile)
  File "/home/aldo/tweakersClone/src/venv_server/lib/python3.9/site-packages/selenium/webdriver/remote/webdriver.py", line 243, in start_session
    response = self.execute(Command.NEW_SESSION, parameters)
  File "/home/aldo/tweakersClone/src/venv_server/lib/python3.9/site-packages/selenium/webdriver/remote/webdriver.py", line 309, in execute
    response = self.command_executor.execute(driver_command, params)
  File "/home/aldo/tweakersClone/src/venv_server/lib/python3.9/site-packages/selenium/webdriver/remote/remote_connection.py", line 460, in execute
    return self._request(command_info[0], url, body=data)
  File "/home/aldo/tweakersClone/src/venv_server/lib/python3.9/site-packages/selenium/webdriver/remote/remote_connection.py", line 484, in _request
    resp = self._conn.getresponse()
  File "/usr/lib/python3.9/http/client.py", line 1349, in getresponse
    response.begin()
  File "/usr/lib/python3.9/http/client.py", line 316, in begin
    version, status, reason = self._read_status()
  File "/usr/lib/python3.9/http/client.py", line 277, in _read_status
    line = str(self.fp.readline(_MAXLINE + 1), "iso-8859-1")
  File "/usr/lib/python3.9/socket.py", line 704, in readinto
    return self._sock.recv_into(b)
  File "/home/aldo/tweakersClone/src/venv_server/lib/python3.9/site-packages/interruptingcow/__init__.py", line 74, in handler
    raise exception
RuntimeError

2022-02-06 10:44:37,850 - ERROR - SSH tunneling attempt 0 FAILED 
Traceback (most recent call last):
  File "/home/aldo/tweakersClone/src/webScraperCommon.py", line 64, in start_tunnel
    tunnel.start()
  File "/home/aldo/tweakersClone/src/venv_server/lib/python3.9/site-packages/sshtunnel.py", line 1331, in start
    self._raise(BaseSSHTunnelForwarderError,
  File "/home/aldo/tweakersClone/src/venv_server/lib/python3.9/site-packages/sshtunnel.py", line 1174, in _raise
    raise exception(reason)
sshtunnel.BaseSSHTunnelForwarderError: Could not establish session to SSH gateway

2022-02-06 10:44:45,858 - ERROR - SSH tunneling attempt 1 FAILED 
Traceback (most recent call last):
  File "/home/aldo/tweakersClone/src/venv_server/lib/python3.9/site-packages/sshtunnel.py", line 1404, in _connect_to_gateway
    self._transport.connect(hostkey=self.ssh_host_key,
  File "/home/aldo/tweakersClone/src/venv_server/lib/python3.9/site-packages/paramiko/transport.py", line 1333, in connect
    self.auth_publickey(username, pkey)
  File "/home/aldo/tweakersClone/src/venv_server/lib/python3.9/site-packages/paramiko/transport.py", line 1580, in auth_publickey
    return self.auth_handler.wait_for_response(my_event)
  File "/home/aldo/tweakersClone/src/venv_server/lib/python3.9/site-packages/paramiko/auth_handler.py", line 250, in wait_for_response
    raise e
paramiko.ssh_exception.AuthenticationException: Authentication failed.

During handling of the above exception, another exception occurred:

Traceback (most recent call last):
  File "/home/aldo/tweakersClone/src/webScraperCommon.py", line 64, in start_tunnel
    tunnel.start()
  File "/home/aldo/tweakersClone/src/venv_server/lib/python3.9/site-packages/sshtunnel.py", line 1329, in start
    self._create_tunnels()
  File "/home/aldo/tweakersClone/src/venv_server/lib/python3.9/site-packages/sshtunnel.py", line 1214, in _create_tunnels
    self._connect_to_gateway()
  File "/home/aldo/tweakersClone/src/venv_server/lib/python3.9/site-packages/sshtunnel.py", line 1411, in _connect_to_gateway
    self._stop_transport()
  File "/home/aldo/tweakersClone/src/venv_server/lib/python3.9/site-packages/sshtunnel.py", line 1463, in _stop_transport
    _srv.shutdown()
  File "/usr/lib/python3.9/socketserver.py", line 252, in shutdown
    self.__is_shut_down.wait()
  File "/usr/lib/python3.9/threading.py", line 574, in wait
    signaled = self._cond.wait(timeout)
  File "/usr/lib/python3.9/threading.py", line 312, in wait
    waiter.acquire()
  File "/home/aldo/tweakersClone/src/venv_server/lib/python3.9/site-packages/interruptingcow/__init__.py", line 74, in handler
    raise exception
RuntimeError

2022-02-06 15:30:59,592 - INFO - Attempt 1 of activating geckodriver
2022-02-06 15:31:07,741 - ERROR - Geckodriver activation attempt 1 FAILED 
Traceback (most recent call last):
  File "/home/aldo/tweakersClone/src/webScraperCommon.py", line 258, in __init__
    self.driver = webdriver.Firefox(executable_path=self.pwd + self.geckodriverExe, options=self.firefox_options)
  File "/home/aldo/tweakersClone/src/venv_server/lib/python3.9/site-packages/selenium/webdriver/firefox/webdriver.py", line 154, in __init__
    RemoteWebDriver.__init__(
  File "/home/aldo/tweakersClone/src/venv_server/lib/python3.9/site-packages/selenium/webdriver/remote/webdriver.py", line 154, in __init__
    self.start_session(desired_capabilities, browser_profile)
  File "/home/aldo/tweakersClone/src/venv_server/lib/python3.9/site-packages/selenium/webdriver/remote/webdriver.py", line 243, in start_session
    response = self.execute(Command.NEW_SESSION, parameters)
  File "/home/aldo/tweakersClone/src/venv_server/lib/python3.9/site-packages/selenium/webdriver/remote/webdriver.py", line 309, in execute
    response = self.command_executor.execute(driver_command, params)
  File "/home/aldo/tweakersClone/src/venv_server/lib/python3.9/site-packages/selenium/webdriver/remote/remote_connection.py", line 460, in execute
    return self._request(command_info[0], url, body=data)
  File "/home/aldo/tweakersClone/src/venv_server/lib/python3.9/site-packages/selenium/webdriver/remote/remote_connection.py", line 484, in _request
    resp = self._conn.getresponse()
  File "/usr/lib/python3.9/http/client.py", line 1349, in getresponse
    response.begin()
  File "/usr/lib/python3.9/http/client.py", line 316, in begin
    version, status, reason = self._read_status()
  File "/usr/lib/python3.9/http/client.py", line 277, in _read_status
    line = str(self.fp.readline(_MAXLINE + 1), "iso-8859-1")
  File "/usr/lib/python3.9/socket.py", line 704, in readinto
    return self._sock.recv_into(b)
  File "/home/aldo/tweakersClone/src/venv_server/lib/python3.9/site-packages/interruptingcow/__init__.py", line 74, in handler
    raise exception
RuntimeError

2022-02-06 15:31:07,744 - INFO - Attempt 2 of activating geckodriver
2022-02-06 15:31:15,886 - ERROR - Geckodriver activation attempt 2 FAILED 
Traceback (most recent call last):
  File "/home/aldo/tweakersClone/src/webScraperCommon.py", line 258, in __init__
    self.driver = webdriver.Firefox(executable_path=self.pwd + self.geckodriverExe, options=self.firefox_options)
  File "/home/aldo/tweakersClone/src/venv_server/lib/python3.9/site-packages/selenium/webdriver/firefox/webdriver.py", line 154, in __init__
    RemoteWebDriver.__init__(
  File "/home/aldo/tweakersClone/src/venv_server/lib/python3.9/site-packages/selenium/webdriver/remote/webdriver.py", line 154, in __init__
    self.start_session(desired_capabilities, browser_profile)
  File "/home/aldo/tweakersClone/src/venv_server/lib/python3.9/site-packages/selenium/webdriver/remote/webdriver.py", line 243, in start_session
    response = self.execute(Command.NEW_SESSION, parameters)
  File "/home/aldo/tweakersClone/src/venv_server/lib/python3.9/site-packages/selenium/webdriver/remote/webdriver.py", line 309, in execute
    response = self.command_executor.execute(driver_command, params)
  File "/home/aldo/tweakersClone/src/venv_server/lib/python3.9/site-packages/selenium/webdriver/remote/remote_connection.py", line 460, in execute
    return self._request(command_info[0], url, body=data)
  File "/home/aldo/tweakersClone/src/venv_server/lib/python3.9/site-packages/selenium/webdriver/remote/remote_connection.py", line 484, in _request
    resp = self._conn.getresponse()
  File "/usr/lib/python3.9/http/client.py", line 1349, in getresponse
    response.begin()
  File "/usr/lib/python3.9/http/client.py", line 316, in begin
    version, status, reason = self._read_status()
  File "/usr/lib/python3.9/http/client.py", line 277, in _read_status
    line = str(self.fp.readline(_MAXLINE + 1), "iso-8859-1")
  File "/usr/lib/python3.9/socket.py", line 704, in readinto
    return self._sock.recv_into(b)
  File "/home/aldo/tweakersClone/src/venv_server/lib/python3.9/site-packages/interruptingcow/__init__.py", line 74, in handler
    raise exception
RuntimeError

2022-02-06 15:31:15,891 - INFO - Attempt 3 of activating geckodriver
2022-02-06 15:31:24,027 - ERROR - Geckodriver activation attempt 3 FAILED 
Traceback (most recent call last):
  File "/home/aldo/tweakersClone/src/webScraperCommon.py", line 258, in __init__
    self.driver = webdriver.Firefox(executable_path=self.pwd + self.geckodriverExe, options=self.firefox_options)
  File "/home/aldo/tweakersClone/src/venv_server/lib/python3.9/site-packages/selenium/webdriver/firefox/webdriver.py", line 154, in __init__
    RemoteWebDriver.__init__(
  File "/home/aldo/tweakersClone/src/venv_server/lib/python3.9/site-packages/selenium/webdriver/remote/webdriver.py", line 154, in __init__
    self.start_session(desired_capabilities, browser_profile)
  File "/home/aldo/tweakersClone/src/venv_server/lib/python3.9/site-packages/selenium/webdriver/remote/webdriver.py", line 243, in start_session
    response = self.execute(Command.NEW_SESSION, parameters)
  File "/home/aldo/tweakersClone/src/venv_server/lib/python3.9/site-packages/selenium/webdriver/remote/webdriver.py", line 309, in execute
    response = self.command_executor.execute(driver_command, params)
  File "/home/aldo/tweakersClone/src/venv_server/lib/python3.9/site-packages/selenium/webdriver/remote/remote_connection.py", line 460, in execute
    return self._request(command_info[0], url, body=data)
  File "/home/aldo/tweakersClone/src/venv_server/lib/python3.9/site-packages/selenium/webdriver/remote/remote_connection.py", line 484, in _request
    resp = self._conn.getresponse()
  File "/usr/lib/python3.9/http/client.py", line 1349, in getresponse
    response.begin()
  File "/usr/lib/python3.9/http/client.py", line 316, in begin
    version, status, reason = self._read_status()
  File "/usr/lib/python3.9/http/client.py", line 277, in _read_status
    line = str(self.fp.readline(_MAXLINE + 1), "iso-8859-1")
  File "/usr/lib/python3.9/socket.py", line 704, in readinto
    return self._sock.recv_into(b)
  File "/home/aldo/tweakersClone/src/venv_server/lib/python3.9/site-packages/interruptingcow/__init__.py", line 74, in handler
    raise exception
RuntimeError

2022-02-06 15:31:24,033 - ERROR - Max attempts to turn on geckodriver reached, traceback: 
Traceback (most recent call last):
  File "/home/aldo/tweakersClone/src/webScraperCommon.py", line 258, in __init__
    self.driver = webdriver.Firefox(executable_path=self.pwd + self.geckodriverExe, options=self.firefox_options)
  File "/home/aldo/tweakersClone/src/venv_server/lib/python3.9/site-packages/selenium/webdriver/firefox/webdriver.py", line 154, in __init__
    RemoteWebDriver.__init__(
  File "/home/aldo/tweakersClone/src/venv_server/lib/python3.9/site-packages/selenium/webdriver/remote/webdriver.py", line 154, in __init__
    self.start_session(desired_capabilities, browser_profile)
  File "/home/aldo/tweakersClone/src/venv_server/lib/python3.9/site-packages/selenium/webdriver/remote/webdriver.py", line 243, in start_session
    response = self.execute(Command.NEW_SESSION, parameters)
  File "/home/aldo/tweakersClone/src/venv_server/lib/python3.9/site-packages/selenium/webdriver/remote/webdriver.py", line 309, in execute
    response = self.command_executor.execute(driver_command, params)
  File "/home/aldo/tweakersClone/src/venv_server/lib/python3.9/site-packages/selenium/webdriver/remote/remote_connection.py", line 460, in execute
    return self._request(command_info[0], url, body=data)
  File "/home/aldo/tweakersClone/src/venv_server/lib/python3.9/site-packages/selenium/webdriver/remote/remote_connection.py", line 484, in _request
    resp = self._conn.getresponse()
  File "/usr/lib/python3.9/http/client.py", line 1349, in getresponse
    response.begin()
  File "/usr/lib/python3.9/http/client.py", line 316, in begin
    version, status, reason = self._read_status()
  File "/usr/lib/python3.9/http/client.py", line 277, in _read_status
    line = str(self.fp.readline(_MAXLINE + 1), "iso-8859-1")
  File "/usr/lib/python3.9/socket.py", line 704, in readinto
    return self._sock.recv_into(b)
  File "/home/aldo/tweakersClone/src/venv_server/lib/python3.9/site-packages/interruptingcow/__init__.py", line 74, in handler
    raise exception
RuntimeError

2022-02-06 15:48:47,686 - INFO - Attempt 1 of activating geckodriver
2022-02-06 15:48:53,428 - INFO - geckodriver successfully activated
2022-02-06 15:49:04,007 - ERROR - Writing to DB failed! 
Traceback (most recent call last):
  File "/home/aldo/tweakersClone/src/venv_server/lib/python3.9/site-packages/sqlalchemy/engine/base.py", line 1802, in _execute_context
    self.dialect.do_execute(
  File "/home/aldo/tweakersClone/src/venv_server/lib/python3.9/site-packages/sqlalchemy/engine/default.py", line 719, in do_execute
    cursor.execute(statement, parameters)
  File "/home/aldo/tweakersClone/src/venv_server/lib/python3.9/site-packages/MySQLdb/cursors.py", line 206, in execute
    res = self._query(query)
  File "/home/aldo/tweakersClone/src/venv_server/lib/python3.9/site-packages/MySQLdb/cursors.py", line 319, in _query
    db.query(q)
  File "/home/aldo/tweakersClone/src/venv_server/lib/python3.9/site-packages/MySQLdb/connections.py", line 254, in query
    _mysql.connection.query(self, query)
MySQLdb._exceptions.DataError: (1406, "Data too long for column 'item' at row 1")

The above exception was the direct cause of the following exception:

Traceback (most recent call last):
  File "/home/aldo/tweakersClone/src/webScraperCommon.py", line 174, in write_to_db
    self.session.commit()
  File "<string>", line 2, in commit
  File "/home/aldo/tweakersClone/src/venv_server/lib/python3.9/site-packages/sqlalchemy/orm/session.py", line 1428, in commit
    self._transaction.commit(_to_root=self.future)
  File "/home/aldo/tweakersClone/src/venv_server/lib/python3.9/site-packages/sqlalchemy/orm/session.py", line 829, in commit
    self._prepare_impl()
  File "/home/aldo/tweakersClone/src/venv_server/lib/python3.9/site-packages/sqlalchemy/orm/session.py", line 808, in _prepare_impl
    self.session.flush()
  File "/home/aldo/tweakersClone/src/venv_server/lib/python3.9/site-packages/sqlalchemy/orm/session.py", line 3345, in flush
    self._flush(objects)
  File "/home/aldo/tweakersClone/src/venv_server/lib/python3.9/site-packages/sqlalchemy/orm/session.py", line 3485, in _flush
    transaction.rollback(_capture_exception=True)
  File "/home/aldo/tweakersClone/src/venv_server/lib/python3.9/site-packages/sqlalchemy/util/langhelpers.py", line 70, in __exit__
    compat.raise_(
  File "/home/aldo/tweakersClone/src/venv_server/lib/python3.9/site-packages/sqlalchemy/util/compat.py", line 207, in raise_
    raise exception
  File "/home/aldo/tweakersClone/src/venv_server/lib/python3.9/site-packages/sqlalchemy/orm/session.py", line 3445, in _flush
    flush_context.execute()
  File "/home/aldo/tweakersClone/src/venv_server/lib/python3.9/site-packages/sqlalchemy/orm/unitofwork.py", line 456, in execute
    rec.execute(self)
  File "/home/aldo/tweakersClone/src/venv_server/lib/python3.9/site-packages/sqlalchemy/orm/unitofwork.py", line 630, in execute
    util.preloaded.orm_persistence.save_obj(
  File "/home/aldo/tweakersClone/src/venv_server/lib/python3.9/site-packages/sqlalchemy/orm/persistence.py", line 244, in save_obj
    _emit_insert_statements(
  File "/home/aldo/tweakersClone/src/venv_server/lib/python3.9/site-packages/sqlalchemy/orm/persistence.py", line 1221, in _emit_insert_statements
    result = connection._execute_20(
  File "/home/aldo/tweakersClone/src/venv_server/lib/python3.9/site-packages/sqlalchemy/engine/base.py", line 1614, in _execute_20
    return meth(self, args_10style, kwargs_10style, execution_options)
  File "/home/aldo/tweakersClone/src/venv_server/lib/python3.9/site-packages/sqlalchemy/sql/elements.py", line 325, in _execute_on_connection
    return connection._execute_clauseelement(
  File "/home/aldo/tweakersClone/src/venv_server/lib/python3.9/site-packages/sqlalchemy/engine/base.py", line 1481, in _execute_clauseelement
    ret = self._execute_context(
  File "/home/aldo/tweakersClone/src/venv_server/lib/python3.9/site-packages/sqlalchemy/engine/base.py", line 1845, in _execute_context
    self._handle_dbapi_exception(
  File "/home/aldo/tweakersClone/src/venv_server/lib/python3.9/site-packages/sqlalchemy/engine/base.py", line 2026, in _handle_dbapi_exception
    util.raise_(
  File "/home/aldo/tweakersClone/src/venv_server/lib/python3.9/site-packages/sqlalchemy/util/compat.py", line 207, in raise_
    raise exception
  File "/home/aldo/tweakersClone/src/venv_server/lib/python3.9/site-packages/sqlalchemy/engine/base.py", line 1802, in _execute_context
    self.dialect.do_execute(
  File "/home/aldo/tweakersClone/src/venv_server/lib/python3.9/site-packages/sqlalchemy/engine/default.py", line 719, in do_execute
    cursor.execute(statement, parameters)
  File "/home/aldo/tweakersClone/src/venv_server/lib/python3.9/site-packages/MySQLdb/cursors.py", line 206, in execute
    res = self._query(query)
  File "/home/aldo/tweakersClone/src/venv_server/lib/python3.9/site-packages/MySQLdb/cursors.py", line 319, in _query
    db.query(q)
  File "/home/aldo/tweakersClone/src/venv_server/lib/python3.9/site-packages/MySQLdb/connections.py", line 254, in query
    _mysql.connection.query(self, query)
sqlalchemy.exc.DataError: (MySQLdb._exceptions.DataError) (1406, "Data too long for column 'item' at row 1")
[SQL: INSERT INTO amazon (`searchTerm`, date, item, price, link) VALUES (%s, %s, %s, %s, %s)]
[parameters: ('sony wf-1000xm3', '6/2/2022 15:48', 'Sony WF-1000XM3 True Wireless Noise Cancelling Oordopjes, Bluetooth, inclusief laadstation, zwart, 1 paar', '139,00', 'amazon.nl/Sony-WF-1000XM3-Cancelling-Oordopjes-laadstation/dp/B07T2FGG2Z/ref=sr_1_5?keywords=SONY+WF-1000XM3&qid=1644162533&sr=8-5')]
(Background on this error at: https://sqlalche.me/e/14/9h9h)

2022-02-06 15:49:04,021 - INFO - Attempt 1 of activating geckodriver
2022-02-06 15:49:09,802 - INFO - geckodriver successfully activated
2022-02-06 15:49:15,410 - INFO - Attempt 1 of activating geckodriver
2022-02-06 15:49:20,821 - INFO - geckodriver successfully activated
2022-02-06 16:25:53,786 - INFO - Attempt 1 of activating geckodriver
2022-02-06 16:25:59,754 - INFO - geckodriver successfully activated
2022-02-06 16:26:06,138 - ERROR - Writing to DB failed! 
Traceback (most recent call last):
  File "/home/aldo/tweakersClone/src/venv_server/lib/python3.9/site-packages/sqlalchemy/engine/base.py", line 1802, in _execute_context
    self.dialect.do_execute(
  File "/home/aldo/tweakersClone/src/venv_server/lib/python3.9/site-packages/sqlalchemy/engine/default.py", line 719, in do_execute
    cursor.execute(statement, parameters)
  File "/home/aldo/tweakersClone/src/venv_server/lib/python3.9/site-packages/MySQLdb/cursors.py", line 206, in execute
    res = self._query(query)
  File "/home/aldo/tweakersClone/src/venv_server/lib/python3.9/site-packages/MySQLdb/cursors.py", line 319, in _query
    db.query(q)
  File "/home/aldo/tweakersClone/src/venv_server/lib/python3.9/site-packages/MySQLdb/connections.py", line 254, in query
    _mysql.connection.query(self, query)
MySQLdb._exceptions.DataError: (1406, "Data too long for column 'link' at row 1")

The above exception was the direct cause of the following exception:

Traceback (most recent call last):
  File "/home/aldo/tweakersClone/src/webScraperCommon.py", line 173, in write_to_db
    self.session.commit()
  File "<string>", line 2, in commit
  File "/home/aldo/tweakersClone/src/venv_server/lib/python3.9/site-packages/sqlalchemy/orm/session.py", line 1428, in commit
    self._transaction.commit(_to_root=self.future)
  File "/home/aldo/tweakersClone/src/venv_server/lib/python3.9/site-packages/sqlalchemy/orm/session.py", line 829, in commit
    self._prepare_impl()
  File "/home/aldo/tweakersClone/src/venv_server/lib/python3.9/site-packages/sqlalchemy/orm/session.py", line 808, in _prepare_impl
    self.session.flush()
  File "/home/aldo/tweakersClone/src/venv_server/lib/python3.9/site-packages/sqlalchemy/orm/session.py", line 3345, in flush
    self._flush(objects)
  File "/home/aldo/tweakersClone/src/venv_server/lib/python3.9/site-packages/sqlalchemy/orm/session.py", line 3485, in _flush
    transaction.rollback(_capture_exception=True)
  File "/home/aldo/tweakersClone/src/venv_server/lib/python3.9/site-packages/sqlalchemy/util/langhelpers.py", line 70, in __exit__
    compat.raise_(
  File "/home/aldo/tweakersClone/src/venv_server/lib/python3.9/site-packages/sqlalchemy/util/compat.py", line 207, in raise_
    raise exception
  File "/home/aldo/tweakersClone/src/venv_server/lib/python3.9/site-packages/sqlalchemy/orm/session.py", line 3445, in _flush
    flush_context.execute()
  File "/home/aldo/tweakersClone/src/venv_server/lib/python3.9/site-packages/sqlalchemy/orm/unitofwork.py", line 456, in execute
    rec.execute(self)
  File "/home/aldo/tweakersClone/src/venv_server/lib/python3.9/site-packages/sqlalchemy/orm/unitofwork.py", line 630, in execute
    util.preloaded.orm_persistence.save_obj(
  File "/home/aldo/tweakersClone/src/venv_server/lib/python3.9/site-packages/sqlalchemy/orm/persistence.py", line 244, in save_obj
    _emit_insert_statements(
  File "/home/aldo/tweakersClone/src/venv_server/lib/python3.9/site-packages/sqlalchemy/orm/persistence.py", line 1221, in _emit_insert_statements
    result = connection._execute_20(
  File "/home/aldo/tweakersClone/src/venv_server/lib/python3.9/site-packages/sqlalchemy/engine/base.py", line 1614, in _execute_20
    return meth(self, args_10style, kwargs_10style, execution_options)
  File "/home/aldo/tweakersClone/src/venv_server/lib/python3.9/site-packages/sqlalchemy/sql/elements.py", line 325, in _execute_on_connection
    return connection._execute_clauseelement(
  File "/home/aldo/tweakersClone/src/venv_server/lib/python3.9/site-packages/sqlalchemy/engine/base.py", line 1481, in _execute_clauseelement
    ret = self._execute_context(
  File "/home/aldo/tweakersClone/src/venv_server/lib/python3.9/site-packages/sqlalchemy/engine/base.py", line 1845, in _execute_context
    self._handle_dbapi_exception(
  File "/home/aldo/tweakersClone/src/venv_server/lib/python3.9/site-packages/sqlalchemy/engine/base.py", line 2026, in _handle_dbapi_exception
    util.raise_(
  File "/home/aldo/tweakersClone/src/venv_server/lib/python3.9/site-packages/sqlalchemy/util/compat.py", line 207, in raise_
    raise exception
  File "/home/aldo/tweakersClone/src/venv_server/lib/python3.9/site-packages/sqlalchemy/engine/base.py", line 1802, in _execute_context
    self.dialect.do_execute(
  File "/home/aldo/tweakersClone/src/venv_server/lib/python3.9/site-packages/sqlalchemy/engine/default.py", line 719, in do_execute
    cursor.execute(statement, parameters)
  File "/home/aldo/tweakersClone/src/venv_server/lib/python3.9/site-packages/MySQLdb/cursors.py", line 206, in execute
    res = self._query(query)
  File "/home/aldo/tweakersClone/src/venv_server/lib/python3.9/site-packages/MySQLdb/cursors.py", line 319, in _query
    db.query(q)
  File "/home/aldo/tweakersClone/src/venv_server/lib/python3.9/site-packages/MySQLdb/connections.py", line 254, in query
    _mysql.connection.query(self, query)
sqlalchemy.exc.DataError: (MySQLdb._exceptions.DataError) (1406, "Data too long for column 'link' at row 1")
[SQL: INSERT INTO amazon (`searchTerm`, date, item, price, link) VALUES (%s, %s, %s, %s, %s)]
[parameters: ('Sony WH-1000XM3', '6/2/2022 16:25', 'NAOGUNH MDR-10R audio kabel Vervangkabel voor compatibel met Sony MDR-10R / MDR-100ABN / MDR-XB950B1 / MDR-1000X / MDR-1ADAC / wh-1000xm3 vervangende audiokabel voor draadloze hoofdtelefoon (150 cm)', '9,59', 'amazon.nl/gp/slredirect/picassoRedirect.html/ref=pa_sp_atf_aps_sr_pg1_1?ie=UTF8&adId=A01700083II4IPVEJA7D&url=%2FNAOGUNH-Vervangkabel-MDR-XB950B1-ver ... (47 characters truncated) ... 3Dsr_1_1_sspa%3Fkeywords%3DSONY%2BWH-1000XM3%26qid%3D1644164759%26sr%3D8-1-spons%26psc%3D1&qualifier=1644164759&id=4467574793315706&widgetName=sp_atf')]
(Background on this error at: https://sqlalche.me/e/14/9h9h)

2022-02-06 16:26:06,149 - INFO - Attempt 1 of activating geckodriver
2022-02-06 16:26:11,436 - INFO - geckodriver successfully activated
2022-02-06 16:26:17,205 - INFO - Attempt 1 of activating geckodriver
2022-02-06 16:26:22,951 - INFO - geckodriver successfully activated
2022-02-06 16:34:55,613 - INFO - Attempt 1 of activating geckodriver
2022-02-06 16:35:00,897 - INFO - geckodriver successfully activated
2022-02-06 16:35:07,730 - INFO - Attempt 1 of activating geckodriver
2022-02-06 16:35:13,878 - INFO - geckodriver successfully activated
2022-02-06 16:35:19,609 - INFO - Attempt 1 of activating geckodriver
2022-02-06 16:35:25,713 - INFO - geckodriver successfully activated
2022-02-06 16:50:04,223 - INFO - Attempt 1 of activating geckodriver
2022-02-06 16:50:10,255 - INFO - geckodriver successfully activated
2022-02-06 16:50:21,613 - INFO - Attempt 1 of activating geckodriver
2022-02-06 16:50:26,706 - INFO - geckodriver successfully activated
2022-02-06 16:50:32,953 - INFO - Attempt 1 of activating geckodriver
2022-02-06 16:50:38,194 - INFO - geckodriver successfully activated
2022-02-06 16:55:03,623 - INFO - Attempt 1 of activating geckodriver
2022-02-06 16:55:10,053 - INFO - geckodriver successfully activated
2022-02-06 16:55:16,213 - INFO - Attempt 1 of activating geckodriver
2022-02-06 16:55:21,537 - INFO - geckodriver successfully activated
2022-02-06 16:55:30,539 - INFO - Attempt 1 of activating geckodriver
2022-02-06 16:55:36,754 - INFO - geckodriver successfully activated
2022-02-06 17:00:04,595 - INFO - Attempt 1 of activating geckodriver
2022-02-06 17:00:10,878 - INFO - geckodriver successfully activated
2022-02-06 17:00:16,533 - INFO - Attempt 1 of activating geckodriver
2022-02-06 17:00:22,042 - INFO - geckodriver successfully activated
2022-02-06 17:00:32,423 - INFO - Attempt 1 of activating geckodriver
2022-02-06 17:00:37,877 - INFO - geckodriver successfully activated
2022-02-07 04:04:13,629 - INFO - Attempt 1 of activating geckodriver
2022-02-07 04:04:20,170 - INFO - geckodriver successfully activated
2022-02-07 04:04:31,340 - INFO - Attempt 1 of activating geckodriver
2022-02-07 04:04:37,169 - INFO - geckodriver successfully activated
2022-02-07 04:04:42,148 - INFO - Attempt 1 of activating geckodriver
2022-02-07 04:04:47,717 - INFO - geckodriver successfully activated
2022-02-08 04:03:04,584 - INFO - Attempt 1 of activating geckodriver
2022-02-08 04:03:09,806 - INFO - geckodriver successfully activated
2022-02-08 04:03:17,906 - INFO - Attempt 1 of activating geckodriver
2022-02-08 04:03:22,588 - INFO - geckodriver successfully activated
2022-02-08 04:03:31,823 - INFO - Attempt 1 of activating geckodriver
2022-02-08 04:03:36,545 - INFO - geckodriver successfully activated
2022-02-17 14:40:45,650 - ERROR - Reading from DB failed! 
Traceback (most recent call last):
  File "c:\Users\320145763\OneDrive\job and portfolio\portfolio and programming\onlineWebscraper\src\env\lib\site-packages\sqlalchemy\engine\base.py", line 3243, in _wrap_pool_connect
    return fn()
  File "c:\Users\320145763\OneDrive\job and portfolio\portfolio and programming\onlineWebscraper\src\env\lib\site-packages\sqlalchemy\pool\base.py", line 310, in connect
    return _ConnectionFairy._checkout(self)
  File "c:\Users\320145763\OneDrive\job and portfolio\portfolio and programming\onlineWebscraper\src\env\lib\site-packages\sqlalchemy\pool\base.py", line 868, in _checkout
    fairy = _ConnectionRecord.checkout(pool)
  File "c:\Users\320145763\OneDrive\job and portfolio\portfolio and programming\onlineWebscraper\src\env\lib\site-packages\sqlalchemy\pool\base.py", line 481, in checkout
    rec._checkin_failed(err, _fairy_was_created=False)
  File "c:\Users\320145763\OneDrive\job and portfolio\portfolio and programming\onlineWebscraper\src\env\lib\site-packages\sqlalchemy\util\langhelpers.py", line 70, in __exit__
    compat.raise_(
  File "c:\Users\320145763\OneDrive\job and portfolio\portfolio and programming\onlineWebscraper\src\env\lib\site-packages\sqlalchemy\util\compat.py", line 207, in raise_
    raise exception
  File "c:\Users\320145763\OneDrive\job and portfolio\portfolio and programming\onlineWebscraper\src\env\lib\site-packages\sqlalchemy\pool\base.py", line 478, in checkout
    dbapi_connection = rec.get_connection()
  File "c:\Users\320145763\OneDrive\job and portfolio\portfolio and programming\onlineWebscraper\src\env\lib\site-packages\sqlalchemy\pool\base.py", line 607, in get_connection
    self.__connect()
  File "c:\Users\320145763\OneDrive\job and portfolio\portfolio and programming\onlineWebscraper\src\env\lib\site-packages\sqlalchemy\pool\base.py", line 666, in __connect
    pool.logger.debug("Error on connect(): %s", e)
  File "c:\Users\320145763\OneDrive\job and portfolio\portfolio and programming\onlineWebscraper\src\env\lib\site-packages\sqlalchemy\util\langhelpers.py", line 70, in __exit__
    compat.raise_(
  File "c:\Users\320145763\OneDrive\job and portfolio\portfolio and programming\onlineWebscraper\src\env\lib\site-packages\sqlalchemy\util\compat.py", line 207, in raise_
    raise exception
  File "c:\Users\320145763\OneDrive\job and portfolio\portfolio and programming\onlineWebscraper\src\env\lib\site-packages\sqlalchemy\pool\base.py", line 661, in __connect
    self.dbapi_connection = connection = pool._invoke_creator(self)
  File "c:\Users\320145763\OneDrive\job and portfolio\portfolio and programming\onlineWebscraper\src\env\lib\site-packages\sqlalchemy\engine\create.py", line 590, in connect
    return dialect.connect(*cargs, **cparams)
  File "c:\Users\320145763\OneDrive\job and portfolio\portfolio and programming\onlineWebscraper\src\env\lib\site-packages\sqlalchemy\engine\default.py", line 584, in connect
    return self.dbapi.connect(*cargs, **cparams)
  File "c:\Users\320145763\OneDrive\job and portfolio\portfolio and programming\onlineWebscraper\src\env\lib\site-packages\MySQLdb\__init__.py", line 123, in Connect
    return Connection(*args, **kwargs)
  File "c:\Users\320145763\OneDrive\job and portfolio\portfolio and programming\onlineWebscraper\src\env\lib\site-packages\MySQLdb\connections.py", line 185, in __init__
    super().__init__(*args, **kwargs2)
MySQLdb._exceptions.OperationalError: (2013, "Lost connection to server at 'handshake: reading initial communication packet', system error: 0")

The above exception was the direct cause of the following exception:

Traceback (most recent call last):
  File "C:\Users\320145763\OneDrive\job and portfolio\portfolio and programming\onlineWebscraper\src\webScraperCommon.py", line 124, in read_from_db
    data = pd.read_sql(sqlQuery, sessionEngine)
  File "c:\Users\320145763\OneDrive\job and portfolio\portfolio and programming\onlineWebscraper\src\env\lib\site-packages\pandas\io\sql.py", line 628, in read_sql
    return pandas_sql.read_query(
  File "c:\Users\320145763\OneDrive\job and portfolio\portfolio and programming\onlineWebscraper\src\env\lib\site-packages\pandas\io\sql.py", line 1579, in read_query
    result = self.execute(*args)
  File "c:\Users\320145763\OneDrive\job and portfolio\portfolio and programming\onlineWebscraper\src\env\lib\site-packages\pandas\io\sql.py", line 1424, in execute
    return self.connectable.execution_options().execute(*args, **kwargs)
  File "<string>", line 2, in execute
  File "c:\Users\320145763\OneDrive\job and portfolio\portfolio and programming\onlineWebscraper\src\env\lib\site-packages\sqlalchemy\util\deprecations.py", line 401, in warned
    return fn(*args, **kwargs)
  File "c:\Users\320145763\OneDrive\job and portfolio\portfolio and programming\onlineWebscraper\src\env\lib\site-packages\sqlalchemy\engine\base.py", line 3138, in execute
    connection = self.connect(close_with_result=True)
  File "c:\Users\320145763\OneDrive\job and portfolio\portfolio and programming\onlineWebscraper\src\env\lib\site-packages\sqlalchemy\engine\base.py", line 3197, in connect
    return self._connection_cls(self, close_with_result=close_with_result)
  File "c:\Users\320145763\OneDrive\job and portfolio\portfolio and programming\onlineWebscraper\src\env\lib\site-packages\sqlalchemy\engine\base.py", line 96, in __init__
    else engine.raw_connection()
  File "c:\Users\320145763\OneDrive\job and portfolio\portfolio and programming\onlineWebscraper\src\env\lib\site-packages\sqlalchemy\engine\base.py", line 3276, in raw_connection
    return self._wrap_pool_connect(self.pool.connect, _connection)
  File "c:\Users\320145763\OneDrive\job and portfolio\portfolio and programming\onlineWebscraper\src\env\lib\site-packages\sqlalchemy\engine\base.py", line 3246, in _wrap_pool_connect
    Connection._handle_dbapi_exception_noconnection(
  File "c:\Users\320145763\OneDrive\job and portfolio\portfolio and programming\onlineWebscraper\src\env\lib\site-packages\sqlalchemy\engine\base.py", line 2100, in _handle_dbapi_exception_noconnection
    util.raise_(
  File "c:\Users\320145763\OneDrive\job and portfolio\portfolio and programming\onlineWebscraper\src\env\lib\site-packages\sqlalchemy\util\compat.py", line 207, in raise_
    raise exception
  File "c:\Users\320145763\OneDrive\job and portfolio\portfolio and programming\onlineWebscraper\src\env\lib\site-packages\sqlalchemy\engine\base.py", line 3243, in _wrap_pool_connect
    return fn()
  File "c:\Users\320145763\OneDrive\job and portfolio\portfolio and programming\onlineWebscraper\src\env\lib\site-packages\sqlalchemy\pool\base.py", line 310, in connect
    return _ConnectionFairy._checkout(self)
  File "c:\Users\320145763\OneDrive\job and portfolio\portfolio and programming\onlineWebscraper\src\env\lib\site-packages\sqlalchemy\pool\base.py", line 868, in _checkout
    fairy = _ConnectionRecord.checkout(pool)
  File "c:\Users\320145763\OneDrive\job and portfolio\portfolio and programming\onlineWebscraper\src\env\lib\site-packages\sqlalchemy\pool\base.py", line 481, in checkout
    rec._checkin_failed(err, _fairy_was_created=False)
  File "c:\Users\320145763\OneDrive\job and portfolio\portfolio and programming\onlineWebscraper\src\env\lib\site-packages\sqlalchemy\util\langhelpers.py", line 70, in __exit__
    compat.raise_(
  File "c:\Users\320145763\OneDrive\job and portfolio\portfolio and programming\onlineWebscraper\src\env\lib\site-packages\sqlalchemy\util\compat.py", line 207, in raise_
    raise exception
  File "c:\Users\320145763\OneDrive\job and portfolio\portfolio and programming\onlineWebscraper\src\env\lib\site-packages\sqlalchemy\pool\base.py", line 478, in checkout
    dbapi_connection = rec.get_connection()
  File "c:\Users\320145763\OneDrive\job and portfolio\portfolio and programming\onlineWebscraper\src\env\lib\site-packages\sqlalchemy\pool\base.py", line 607, in get_connection
    self.__connect()
  File "c:\Users\320145763\OneDrive\job and portfolio\portfolio and programming\onlineWebscraper\src\env\lib\site-packages\sqlalchemy\pool\base.py", line 666, in __connect
    pool.logger.debug("Error on connect(): %s", e)
  File "c:\Users\320145763\OneDrive\job and portfolio\portfolio and programming\onlineWebscraper\src\env\lib\site-packages\sqlalchemy\util\langhelpers.py", line 70, in __exit__
    compat.raise_(
  File "c:\Users\320145763\OneDrive\job and portfolio\portfolio and programming\onlineWebscraper\src\env\lib\site-packages\sqlalchemy\util\compat.py", line 207, in raise_
    raise exception
  File "c:\Users\320145763\OneDrive\job and portfolio\portfolio and programming\onlineWebscraper\src\env\lib\site-packages\sqlalchemy\pool\base.py", line 661, in __connect
    self.dbapi_connection = connection = pool._invoke_creator(self)
  File "c:\Users\320145763\OneDrive\job and portfolio\portfolio and programming\onlineWebscraper\src\env\lib\site-packages\sqlalchemy\engine\create.py", line 590, in connect
    return dialect.connect(*cargs, **cparams)
  File "c:\Users\320145763\OneDrive\job and portfolio\portfolio and programming\onlineWebscraper\src\env\lib\site-packages\sqlalchemy\engine\default.py", line 584, in connect
    return self.dbapi.connect(*cargs, **cparams)
  File "c:\Users\320145763\OneDrive\job and portfolio\portfolio and programming\onlineWebscraper\src\env\lib\site-packages\MySQLdb\__init__.py", line 123, in Connect
    return Connection(*args, **kwargs)
  File "c:\Users\320145763\OneDrive\job and portfolio\portfolio and programming\onlineWebscraper\src\env\lib\site-packages\MySQLdb\connections.py", line 185, in __init__
    super().__init__(*args, **kwargs2)
sqlalchemy.exc.OperationalError: (MySQLdb._exceptions.OperationalError) (2013, "Lost connection to server at 'handshake: reading initial communication packet', system error: 0")
(Background on this error at: https://sqlalche.me/e/14/e3q8)

2022-02-18 16:58:12,303 - ERROR - Credentials of database not available, traceback: 
Traceback (most recent call last):
  File "C:\Users\aldo-\OneDrive\job and portfolio\portfolio and programming\onlineWebscraper\src\visualizeScrapedData.py", line 65, in <module>
    username = os.environ["tweakersCloneUsername"]
  File "C:\Users\aldo-\AppData\Local\Programs\Python\Python39\lib\os.py", line 679, in __getitem__
    raise KeyError(key) from None
KeyError: 'tweakersCloneUsername'

2022-02-18 16:58:22,950 - ERROR - Credentials of database not available, traceback: 
Traceback (most recent call last):
  File "C:\Users\aldo-\OneDrive\job and portfolio\portfolio and programming\onlineWebscraper\src\visualizeScrapedData.py", line 65, in <module>
    username = os.environ["tweakersCloneUsername"]
  File "C:\Users\aldo-\AppData\Local\Programs\Python\Python39\lib\os.py", line 679, in __getitem__
    raise KeyError(key) from None
KeyError: 'tweakersCloneUsername'

2022-02-20 08:30:07,897 - INFO - Attempt 1 of activating geckodriver
2022-02-20 08:30:13,154 - INFO - geckodriver successfully activated
2022-02-20 08:32:03,491 - INFO - Attempt 1 of activating geckodriver
2022-02-20 08:32:08,648 - INFO - geckodriver successfully activated
2022-02-20 08:32:28,606 - INFO - Attempt 1 of activating geckodriver
2022-02-20 08:32:33,263 - INFO - geckodriver successfully activated
2022-02-20 16:57:56,495 - ERROR - URI for DB not attainable, : 
Traceback (most recent call last):
  File "C:\Users\aldo-\OneDrive\job and portfolio\portfolio and programming\onlineWebscraper\src\webScraperCommon.py", line 63, in start_tunnel
    with timeout(TIMEOUT,exception=RuntimeError):
  File "c:\Users\aldo-\OneDrive\job and portfolio\portfolio and programming\onlineWebscraper\src\env_ROG\lib\site-packages\interruptingcow\__init__.py", line 148, in __enter__
    return super(Timeout, self).__enter__()
  File "c:\Users\aldo-\OneDrive\job and portfolio\portfolio and programming\onlineWebscraper\src\env_ROG\lib\site-packages\interruptingcow\compat.py", line 14, in __enter__
    return self.gen.__next__()
  File "c:\Users\aldo-\OneDrive\job and portfolio\portfolio and programming\onlineWebscraper\src\env_ROG\lib\site-packages\interruptingcow\__init__.py", line 97, in timeout
    set_sighandler()
  File "c:\Users\aldo-\OneDrive\job and portfolio\portfolio and programming\onlineWebscraper\src\env_ROG\lib\site-packages\interruptingcow\__init__.py", line 77, in set_sighandler
    current = signal.getsignal(signal.SIGALRM)
AttributeError: module 'signal' has no attribute 'SIGALRM'

During handling of the above exception, another exception occurred:

Traceback (most recent call last):
  File "C:\Users\aldo-\OneDrive\job and portfolio\portfolio and programming\onlineWebscraper\src\visualizeScrapedData.py", line 74, in <module>
    sshFunctions.start_tunnel()
  File "C:\Users\aldo-\OneDrive\job and portfolio\portfolio and programming\onlineWebscraper\src\webScraperCommon.py", line 70, in start_tunnel
    tunnel.start()
  File "c:\Users\aldo-\OneDrive\job and portfolio\portfolio and programming\onlineWebscraper\src\env_ROG\lib\site-packages\sshtunnel.py", line 1331, in start
    self._raise(BaseSSHTunnelForwarderError,
  File "c:\Users\aldo-\OneDrive\job and portfolio\portfolio and programming\onlineWebscraper\src\env_ROG\lib\site-packages\sshtunnel.py", line 1174, in _raise
    raise exception(reason)
sshtunnel.BaseSSHTunnelForwarderError: Could not establish session to SSH gateway

2022-02-20 16:58:48,792 - ERROR - URI for DB not attainable, : 
Traceback (most recent call last):
  File "C:\Users\aldo-\OneDrive\job and portfolio\portfolio and programming\onlineWebscraper\src\webScraperCommon.py", line 63, in start_tunnel
    with timeout(TIMEOUT,exception=RuntimeError):
  File "c:\Users\aldo-\OneDrive\job and portfolio\portfolio and programming\onlineWebscraper\src\env_ROG\lib\site-packages\interruptingcow\__init__.py", line 148, in __enter__
    return super(Timeout, self).__enter__()
  File "c:\Users\aldo-\OneDrive\job and portfolio\portfolio and programming\onlineWebscraper\src\env_ROG\lib\site-packages\interruptingcow\compat.py", line 14, in __enter__
    return self.gen.__next__()
  File "c:\Users\aldo-\OneDrive\job and portfolio\portfolio and programming\onlineWebscraper\src\env_ROG\lib\site-packages\interruptingcow\__init__.py", line 97, in timeout
    set_sighandler()
  File "c:\Users\aldo-\OneDrive\job and portfolio\portfolio and programming\onlineWebscraper\src\env_ROG\lib\site-packages\interruptingcow\__init__.py", line 77, in set_sighandler
    current = signal.getsignal(signal.SIGALRM)
AttributeError: module 'signal' has no attribute 'SIGALRM'

During handling of the above exception, another exception occurred:

Traceback (most recent call last):
  File "C:\Users\aldo-\OneDrive\job and portfolio\portfolio and programming\onlineWebscraper\src\visualizeScrapedData.py", line 74, in <module>
    sshFunctions.start_tunnel()
  File "C:\Users\aldo-\OneDrive\job and portfolio\portfolio and programming\onlineWebscraper\src\webScraperCommon.py", line 70, in start_tunnel
    tunnel.start()
  File "c:\Users\aldo-\OneDrive\job and portfolio\portfolio and programming\onlineWebscraper\src\env_ROG\lib\site-packages\sshtunnel.py", line 1331, in start
    self._raise(BaseSSHTunnelForwarderError,
  File "c:\Users\aldo-\OneDrive\job and portfolio\portfolio and programming\onlineWebscraper\src\env_ROG\lib\site-packages\sshtunnel.py", line 1174, in _raise
    raise exception(reason)
sshtunnel.BaseSSHTunnelForwarderError: Could not establish session to SSH gateway

2022-02-21 16:16:37,465 - ERROR - URI for DB not attainable, : 
Traceback (most recent call last):
  File "C:\Users\320145763\OneDrive\job and portfolio\portfolio and programming\onlineWebscraper\src\webScraperCommon.py", line 63, in start_tunnel
    with timeout(TIMEOUT,exception=RuntimeError):
  File "c:\Users\320145763\OneDrive\job and portfolio\portfolio and programming\onlineWebscraper\src\env\lib\site-packages\interruptingcow\__init__.py", line 148, in __enter__
    return super(Timeout, self).__enter__()
  File "c:\Users\320145763\OneDrive\job and portfolio\portfolio and programming\onlineWebscraper\src\env\lib\site-packages\interruptingcow\compat.py", line 14, in __enter__
    return self.gen.__next__()
  File "c:\Users\320145763\OneDrive\job and portfolio\portfolio and programming\onlineWebscraper\src\env\lib\site-packages\interruptingcow\__init__.py", line 97, in timeout
    set_sighandler()
  File "c:\Users\320145763\OneDrive\job and portfolio\portfolio and programming\onlineWebscraper\src\env\lib\site-packages\interruptingcow\__init__.py", line 77, in set_sighandler
    current = signal.getsignal(signal.SIGALRM)
AttributeError: module 'signal' has no attribute 'SIGALRM'

During handling of the above exception, another exception occurred:

Traceback (most recent call last):
  File "C:\Users\320145763\OneDrive\job and portfolio\portfolio and programming\onlineWebscraper\src\visualizeScrapedData.py", line 74, in <module>
    sshFunctions.start_tunnel()
  File "C:\Users\320145763\OneDrive\job and portfolio\portfolio and programming\onlineWebscraper\src\webScraperCommon.py", line 70, in start_tunnel
    tunnel.start()
  File "c:\Users\320145763\OneDrive\job and portfolio\portfolio and programming\onlineWebscraper\src\env\lib\site-packages\sshtunnel.py", line 1331, in start
    self._raise(BaseSSHTunnelForwarderError,
  File "c:\Users\320145763\OneDrive\job and portfolio\portfolio and programming\onlineWebscraper\src\env\lib\site-packages\sshtunnel.py", line 1174, in _raise
    raise exception(reason)
sshtunnel.BaseSSHTunnelForwarderError: Could not establish session to SSH gateway

