2022-01-28 15:23:04,400 - ERROR - Some error happened during scraping
2022-01-30 09:49:20,807 - ERROR - Timeout in tunneling
2022-01-30 10:10:47,173 - ERROR - Timeout in tunneling
2022-01-30 10:23:34,108 - ERROR - Timeout in tunneling
2022-01-30 15:25:34,750 - ERROR - Timeout in tunneling
2022-01-30 15:33:00,598 - ERROR - Timeout in tunneling
2022-01-30 15:34:30,520 - ERROR - Timeout in tunneling
2022-01-30 15:36:44,823 - ERROR - Timeout in tunneling
2022-01-30 15:39:43,444 - ERROR - Timeout in tunneling
2022-01-30 15:44:15,965 - ERROR - NoneType: None

2022-01-30 15:45:33,981 - ERROR - <function format_exc at 0x7f823d369700>
2022-01-30 15:46:16,224 - ERROR - Traceback (most recent call last):
  File "/home/aldo/tweakersClone/src/webScraperCommon.py", line 64, in _tunnelToDatabaseServer
    time.sleep(14)
  File "/home/aldo/tweakersClone/src/venv_server/lib/python3.9/site-packages/interruptingcow/__init__.py", line 74, in handler
    raise exception
RuntimeError

2022-01-30 15:49:42,825 - ERROR - Timeout in tunneling, traceback: 
Traceback (most recent call last):
  File "/home/aldo/tweakersClone/src/webScraperCommon.py", line 64, in _tunnelToDatabaseServer
    time.sleep(14)
  File "/home/aldo/tweakersClone/src/venv_server/lib/python3.9/site-packages/interruptingcow/__init__.py", line 74, in handler
    raise exception
RuntimeError

2022-01-30 15:54:03,249 - ERROR - Timeout in tunneling, traceback: 
Traceback (most recent call last):
  File "/home/aldo/tweakersClone/src/webScraperCommon.py", line 64, in _tunnelToDatabaseServer
    time.sleep(14)
  File "/home/aldo/tweakersClone/src/venv_server/lib/python3.9/site-packages/interruptingcow/__init__.py", line 74, in handler
    raise exception
RuntimeError

2022-01-30 15:55:41,227 - ERROR - Timeout in tunneling, traceback: 
Traceback (most recent call last):
  File "/home/aldo/tweakersClone/src/webScraperCommon.py", line 64, in _tunnelToDatabaseServer
    time.sleep(14)
  File "/home/aldo/tweakersClone/src/venv_server/lib/python3.9/site-packages/interruptingcow/__init__.py", line 74, in handler
    raise exception
RuntimeError

2022-01-30 16:44:53,121 - ERROR - Timeout in tunneling, traceback: 
Traceback (most recent call last):
  File "/home/aldo/tweakersClone/src/webScraperCommon.py", line 64, in _tunnelToDatabaseServer
    time.sleep(14)
  File "/home/aldo/tweakersClone/src/venv_server/lib/python3.9/site-packages/interruptingcow/__init__.py", line 74, in handler
    raise exception
RuntimeError

2022-01-30 16:44:53,122 - ERROR - dbURI not attainable, error: Traceback (most recent call last):
  File "/home/aldo/tweakersClone/src/visualizeScrapedData.py", line 62, in <module>
    dbURI = SSHTunnelOperations("aldosebastian","25803conan","mysql","dateItemPrice").getURI()
  File "/home/aldo/tweakersClone/src/webScraperCommon.py", line 43, in getURI
    {self._tunnelToDatabaseServer().local_bind_port}/{self.username}${self.schema}'
  File "/home/aldo/tweakersClone/src/webScraperCommon.py", line 75, in _tunnelToDatabaseServer
    raise tunnelingTimeoutException(msg = exceptionMsg)
customExceptions.tunnelingTimeoutException: Traceback (most recent call last):
  File "/home/aldo/tweakersClone/src/webScraperCommon.py", line 64, in _tunnelToDatabaseServer
    time.sleep(14)
  File "/home/aldo/tweakersClone/src/venv_server/lib/python3.9/site-packages/interruptingcow/__init__.py", line 74, in handler
    raise exception
RuntimeError


2022-01-30 17:50:19,243 - ERROR - Credentials of database not available, traceback: 
Traceback (most recent call last):
  File "/home/aldo/tweakersClone/src/coolblueScraper.py", line 47, in main
    password = os.environ["tweakersClonePasswor"]
  File "/usr/lib/python3.9/os.py", line 679, in __getitem__
    raise KeyError(key) from None
KeyError: 'tweakersClonePasswor'

2022-01-31 04:03:03,772 - ERROR - Credentials of database not available, traceback: 
Traceback (most recent call last):
  File "/home/aldo/tweakersClone/src/coolblueScraper.py", line 46, in main
    username = os.environ["tweakersCloneUsername"]
  File "/usr/lib/python3.9/os.py", line 679, in __getitem__
    raise KeyError(key) from None
KeyError: 'tweakersCloneUsername'

2022-01-31 07:21:59,106 - ERROR - Credentials of database not available, traceback: 
Traceback (most recent call last):
  File "/home/aldo/tweakersClone/src/coolblueScraper.py", line 47, in main
    password = os.environ["tweakersClonePasswod"]
  File "/usr/lib/python3.9/os.py", line 679, in __getitem__
    raise KeyError(key) from None
KeyError: 'tweakersClonePasswod'

2022-01-31 07:30:27,603 - INFO - Attempt 1 of activating geckodriver
2022-01-31 07:30:55,393 - ERROR - dbURI not attainable, : 
Traceback (most recent call last):
  File "/home/aldo/tweakersClone/src/webScraperCommon.py", line 66, in _tunnelToDatabaseServer
    time.sleep(14)
  File "/home/aldo/tweakersClone/src/venv_server/lib/python3.9/site-packages/interruptingcow/__init__.py", line 74, in handler
    raise exception
RuntimeError

During handling of the above exception, another exception occurred:

Traceback (most recent call last):
  File "/home/aldo/tweakersClone/src/visualizeScrapedData.py", line 62, in <module>
    dbURI = SSHTunnelOperations("aldosebastian","25803conan","mysql","dateItemPrice").getURI()
  File "/home/aldo/tweakersClone/src/webScraperCommon.py", line 45, in getURI
    {self._tunnelToDatabaseServer().local_bind_port}/{self.username}${self.schema}'
  File "/home/aldo/tweakersClone/src/webScraperCommon.py", line 73, in _tunnelToDatabaseServer
    scraperLogger(level = "ERROR", msg = f"SSH tunneling attempt {i} FAILED \n" \
TypeError: can only concatenate str (not "NoneType") to str

2022-01-31 09:22:57,593 - INFO - Attempt 1 of activating geckodriver
2022-01-31 09:24:03,637 - INFO - Attempt 1 of activating geckodriver
2022-01-31 09:24:10,665 - INFO - geckodriver successfully activated
2022-01-31 09:24:15,105 - ERROR - Some error happened during scraping: Traceback (most recent call last):
  File "/home/aldo/tweakersClone/src/webScraperCommon.py", line 217, in scrapeStore
    self.extract_record(self.searchTerm,self.soup,self.itemPriceLink,self.storeName)
TypeError: extract_record() missing 1 required positional argument: 'storeName'

2022-01-31 10:34:00,369 - ERROR - Credentials of database not available, traceback: 
Traceback (most recent call last):
  File "src/amazonScraper.py", line 46, in main
    username = os.environ["tweakersCloneUsername"]
  File "C:\Users\320145763\AppData\Local\Programs\Python\Python39\lib\os.py", line 679, in __getitem__
    raise KeyError(key) from None
KeyError: 'tweakersCloneUsername'

2022-01-31 10:35:09,672 - ERROR - Credentials of database not available, traceback: 
Traceback (most recent call last):
  File "src/amazonScraper.py", line 46, in main
    username = os.environ["tweakersCloneUsername"]
  File "C:\Users\320145763\AppData\Local\Programs\Python\Python39\lib\os.py", line 679, in __getitem__
    raise KeyError(key) from None
KeyError: 'tweakersCloneUsername'

2022-01-31 10:35:49,890 - ERROR - Credentials of database not available, traceback: 
Traceback (most recent call last):
  File "src/amazonScraper.py", line 46, in main
    username = os.environ["tweakersCloneUsername"]
  File "C:\Users\320145763\AppData\Local\Programs\Python\Python39\lib\os.py", line 679, in __getitem__
    raise KeyError(key) from None
KeyError: 'tweakersCloneUsername'

2022-01-31 10:41:15,401 - ERROR - Credentials of database not available, traceback: 
Traceback (most recent call last):
  File "src/amazonScraper.py", line 46, in main
    username = os.environ["tweakersCloneUsername"]
  File "C:\Users\320145763\AppData\Local\Programs\Python\Python39\lib\os.py", line 679, in __getitem__
    raise KeyError(key) from None
KeyError: 'tweakersCloneUsername'

2022-01-31 10:47:21,317 - INFO - Attempt 1 of activating geckodriver
2022-01-31 10:47:26,492 - INFO - geckodriver successfully activated
2022-01-31 10:47:43,811 - INFO - Attempt 1 of activating geckodriver
2022-01-31 10:47:49,010 - INFO - geckodriver successfully activated
2022-01-31 11:28:23,110 - INFO - Attempt 1 of activating geckodriver
2022-01-31 11:28:28,299 - INFO - geckodriver successfully activated
2022-01-31 11:30:03,815 - INFO - Attempt 1 of activating geckodriver
2022-01-31 11:30:08,999 - INFO - geckodriver successfully activated
2022-01-31 11:30:48,329 - INFO - Attempt 1 of activating geckodriver
2022-01-31 11:30:54,002 - INFO - geckodriver successfully activated
2022-01-31 11:45:21,127 - INFO - Attempt 1 of activating geckodriver
2022-01-31 11:45:26,328 - INFO - geckodriver successfully activated
2022-01-31 11:49:27,057 - INFO - Attempt 1 of activating geckodriver
2022-01-31 11:49:32,752 - INFO - geckodriver successfully activated
2022-01-31 11:50:17,627 - INFO - Attempt 1 of activating geckodriver
2022-01-31 11:50:23,356 - INFO - geckodriver successfully activated
2022-01-31 11:59:46,206 - INFO - Attempt 1 of activating geckodriver
2022-01-31 11:59:51,387 - INFO - geckodriver successfully activated
2022-01-31 11:59:57,275 - ERROR - Some error happened during scraping: Traceback (most recent call last):
  File "C:\Users\320145763\OneDrive\job and portfolio\portfolio and programming\onlineWebscraper\src\webScraperCommon.py", line 229, in scrapeStore
    self.extract_record(self.searchTerm,self.soup,self.itemPriceLink,self.storeName)
TypeError: extract_record() missing 1 required positional argument: 'storeName'

2022-01-31 12:02:10,761 - INFO - Attempt 1 of activating geckodriver
2022-01-31 12:02:16,440 - INFO - geckodriver successfully activated
2022-02-01 04:03:04,324 - ERROR - Credentials of database not available, traceback: 
Traceback (most recent call last):
  File "/home/aldo/tweakersClone/src/coolblueScraper.py", line 46, in main
    username = os.environ["tweakersCloneUsername"]
  File "/usr/lib/python3.9/os.py", line 679, in __getitem__
    raise KeyError(key) from None
KeyError: 'tweakersCloneUsername'

2022-02-01 14:16:59,354 - INFO - Attempt 1 of activating geckodriver
2022-02-01 14:21:43,695 - INFO - Attempt 1 of activating geckodriver
2022-02-01 14:21:45,303 - ERROR - Geckodriver activation attempt 2 FAILED 
Traceback (most recent call last):
  File "/home/aldo/tweakersClone/src/webScraperCommon.py", line 209, in __init__
    self.driver = webdriver.Firefox(executable_path=self.pwd + self.geckodriverExe, options=self.firefox_options)
  File "/home/aldo/tweakersClone/src/venv_server/lib/python3.9/site-packages/selenium/webdriver/firefox/webdriver.py", line 154, in __init__
    RemoteWebDriver.__init__(
  File "/home/aldo/tweakersClone/src/venv_server/lib/python3.9/site-packages/selenium/webdriver/remote/webdriver.py", line 154, in __init__
    self.start_session(desired_capabilities, browser_profile)
  File "/home/aldo/tweakersClone/src/venv_server/lib/python3.9/site-packages/selenium/webdriver/remote/webdriver.py", line 243, in start_session
    response = self.execute(Command.NEW_SESSION, parameters)
  File "/home/aldo/tweakersClone/src/venv_server/lib/python3.9/site-packages/selenium/webdriver/remote/webdriver.py", line 311, in execute
    self.error_handler.check_response(response)
  File "/home/aldo/tweakersClone/src/venv_server/lib/python3.9/site-packages/selenium/webdriver/remote/errorhandler.py", line 237, in check_response
    raise exception_class(message, screen, stacktrace)
selenium.common.exceptions.WebDriverException: Message: Process unexpectedly closed with status 1


2022-02-01 14:21:45,306 - INFO - Attempt 2 of activating geckodriver
2022-02-01 14:21:46,803 - ERROR - Geckodriver activation attempt 3 FAILED 
Traceback (most recent call last):
  File "/home/aldo/tweakersClone/src/webScraperCommon.py", line 209, in __init__
    self.driver = webdriver.Firefox(executable_path=self.pwd + self.geckodriverExe, options=self.firefox_options)
  File "/home/aldo/tweakersClone/src/venv_server/lib/python3.9/site-packages/selenium/webdriver/firefox/webdriver.py", line 154, in __init__
    RemoteWebDriver.__init__(
  File "/home/aldo/tweakersClone/src/venv_server/lib/python3.9/site-packages/selenium/webdriver/remote/webdriver.py", line 154, in __init__
    self.start_session(desired_capabilities, browser_profile)
  File "/home/aldo/tweakersClone/src/venv_server/lib/python3.9/site-packages/selenium/webdriver/remote/webdriver.py", line 243, in start_session
    response = self.execute(Command.NEW_SESSION, parameters)
  File "/home/aldo/tweakersClone/src/venv_server/lib/python3.9/site-packages/selenium/webdriver/remote/webdriver.py", line 311, in execute
    self.error_handler.check_response(response)
  File "/home/aldo/tweakersClone/src/venv_server/lib/python3.9/site-packages/selenium/webdriver/remote/errorhandler.py", line 237, in check_response
    raise exception_class(message, screen, stacktrace)
selenium.common.exceptions.WebDriverException: Message: Process unexpectedly closed with status 1


2022-02-01 14:21:46,808 - INFO - Attempt 3 of activating geckodriver
2022-02-01 14:21:48,200 - ERROR - Geckodriver activation attempt 4 FAILED 
Traceback (most recent call last):
  File "/home/aldo/tweakersClone/src/webScraperCommon.py", line 209, in __init__
    self.driver = webdriver.Firefox(executable_path=self.pwd + self.geckodriverExe, options=self.firefox_options)
  File "/home/aldo/tweakersClone/src/venv_server/lib/python3.9/site-packages/selenium/webdriver/firefox/webdriver.py", line 154, in __init__
    RemoteWebDriver.__init__(
  File "/home/aldo/tweakersClone/src/venv_server/lib/python3.9/site-packages/selenium/webdriver/remote/webdriver.py", line 154, in __init__
    self.start_session(desired_capabilities, browser_profile)
  File "/home/aldo/tweakersClone/src/venv_server/lib/python3.9/site-packages/selenium/webdriver/remote/webdriver.py", line 243, in start_session
    response = self.execute(Command.NEW_SESSION, parameters)
  File "/home/aldo/tweakersClone/src/venv_server/lib/python3.9/site-packages/selenium/webdriver/remote/webdriver.py", line 311, in execute
    self.error_handler.check_response(response)
  File "/home/aldo/tweakersClone/src/venv_server/lib/python3.9/site-packages/selenium/webdriver/remote/errorhandler.py", line 237, in check_response
    raise exception_class(message, screen, stacktrace)
selenium.common.exceptions.WebDriverException: Message: Process unexpectedly closed with status 1


2022-02-01 14:21:48,208 - ERROR - Some error happened during scraping: Traceback (most recent call last):
  File "/home/aldo/tweakersClone/src/webScraperCommon.py", line 233, in scrapeStore
    self.driver.get(self._get_url(page))
AttributeError: 'Scrape' object has no attribute 'driver'

2022-02-01 14:22:47,768 - INFO - Attempt 1 of activating geckodriver
2022-02-01 14:22:49,631 - ERROR - Geckodriver activation attempt 2 FAILED 
Traceback (most recent call last):
  File "/home/aldo/tweakersClone/src/webScraperCommon.py", line 209, in __init__
    self.driver = webdriver.Firefox(executable_path=self.pwd + self.geckodriverExe, options=self.firefox_options)
  File "/home/aldo/tweakersClone/src/venv_server/lib/python3.9/site-packages/selenium/webdriver/firefox/webdriver.py", line 154, in __init__
    RemoteWebDriver.__init__(
  File "/home/aldo/tweakersClone/src/venv_server/lib/python3.9/site-packages/selenium/webdriver/remote/webdriver.py", line 154, in __init__
    self.start_session(desired_capabilities, browser_profile)
  File "/home/aldo/tweakersClone/src/venv_server/lib/python3.9/site-packages/selenium/webdriver/remote/webdriver.py", line 243, in start_session
    response = self.execute(Command.NEW_SESSION, parameters)
  File "/home/aldo/tweakersClone/src/venv_server/lib/python3.9/site-packages/selenium/webdriver/remote/webdriver.py", line 311, in execute
    self.error_handler.check_response(response)
  File "/home/aldo/tweakersClone/src/venv_server/lib/python3.9/site-packages/selenium/webdriver/remote/errorhandler.py", line 237, in check_response
    raise exception_class(message, screen, stacktrace)
selenium.common.exceptions.WebDriverException: Message: Process unexpectedly closed with status 1


2022-02-01 14:22:49,639 - INFO - Attempt 2 of activating geckodriver
2022-02-01 14:22:51,138 - ERROR - Geckodriver activation attempt 3 FAILED 
Traceback (most recent call last):
  File "/home/aldo/tweakersClone/src/webScraperCommon.py", line 209, in __init__
    self.driver = webdriver.Firefox(executable_path=self.pwd + self.geckodriverExe, options=self.firefox_options)
  File "/home/aldo/tweakersClone/src/venv_server/lib/python3.9/site-packages/selenium/webdriver/firefox/webdriver.py", line 154, in __init__
    RemoteWebDriver.__init__(
  File "/home/aldo/tweakersClone/src/venv_server/lib/python3.9/site-packages/selenium/webdriver/remote/webdriver.py", line 154, in __init__
    self.start_session(desired_capabilities, browser_profile)
  File "/home/aldo/tweakersClone/src/venv_server/lib/python3.9/site-packages/selenium/webdriver/remote/webdriver.py", line 243, in start_session
    response = self.execute(Command.NEW_SESSION, parameters)
  File "/home/aldo/tweakersClone/src/venv_server/lib/python3.9/site-packages/selenium/webdriver/remote/webdriver.py", line 311, in execute
    self.error_handler.check_response(response)
  File "/home/aldo/tweakersClone/src/venv_server/lib/python3.9/site-packages/selenium/webdriver/remote/errorhandler.py", line 237, in check_response
    raise exception_class(message, screen, stacktrace)
selenium.common.exceptions.WebDriverException: Message: Process unexpectedly closed with status 1


2022-02-01 14:22:51,141 - INFO - Attempt 3 of activating geckodriver
2022-02-01 14:22:52,643 - ERROR - Geckodriver activation attempt 4 FAILED 
Traceback (most recent call last):
  File "/home/aldo/tweakersClone/src/webScraperCommon.py", line 209, in __init__
    self.driver = webdriver.Firefox(executable_path=self.pwd + self.geckodriverExe, options=self.firefox_options)
  File "/home/aldo/tweakersClone/src/venv_server/lib/python3.9/site-packages/selenium/webdriver/firefox/webdriver.py", line 154, in __init__
    RemoteWebDriver.__init__(
  File "/home/aldo/tweakersClone/src/venv_server/lib/python3.9/site-packages/selenium/webdriver/remote/webdriver.py", line 154, in __init__
    self.start_session(desired_capabilities, browser_profile)
  File "/home/aldo/tweakersClone/src/venv_server/lib/python3.9/site-packages/selenium/webdriver/remote/webdriver.py", line 243, in start_session
    response = self.execute(Command.NEW_SESSION, parameters)
  File "/home/aldo/tweakersClone/src/venv_server/lib/python3.9/site-packages/selenium/webdriver/remote/webdriver.py", line 311, in execute
    self.error_handler.check_response(response)
  File "/home/aldo/tweakersClone/src/venv_server/lib/python3.9/site-packages/selenium/webdriver/remote/errorhandler.py", line 237, in check_response
    raise exception_class(message, screen, stacktrace)
selenium.common.exceptions.WebDriverException: Message: Process unexpectedly closed with status 1


2022-02-01 14:22:52,648 - ERROR - Some error happened during scraping: Traceback (most recent call last):
  File "/home/aldo/tweakersClone/src/webScraperCommon.py", line 233, in scrapeStore
    self.driver.get(self._get_url(page))
AttributeError: 'Scrape' object has no attribute 'driver'

2022-02-01 14:27:58,087 - ERROR - SSH tunneling attempt 1 FAILED 
Traceback (most recent call last):
  File "/home/aldo/tweakersClone/src/webScraperCommon.py", line 67, in _tunnelToDatabaseServer
    tunnel.start()
  File "/home/aldo/tweakersClone/src/venv_server/lib/python3.9/site-packages/sshtunnel.py", line 1329, in start
    self._create_tunnels()
  File "/home/aldo/tweakersClone/src/venv_server/lib/python3.9/site-packages/sshtunnel.py", line 1214, in _create_tunnels
    self._connect_to_gateway()
  File "/home/aldo/tweakersClone/src/venv_server/lib/python3.9/site-packages/sshtunnel.py", line 1404, in _connect_to_gateway
    self._transport.connect(hostkey=self.ssh_host_key,
  File "/home/aldo/tweakersClone/src/venv_server/lib/python3.9/site-packages/paramiko/transport.py", line 1291, in connect
    self.start_client()
  File "/home/aldo/tweakersClone/src/venv_server/lib/python3.9/site-packages/paramiko/transport.py", line 656, in start_client
    event.wait(0.1)
  File "/usr/lib/python3.9/threading.py", line 574, in wait
    signaled = self._cond.wait(timeout)
  File "/usr/lib/python3.9/threading.py", line 321, in wait
    self._acquire_restore(saved_state)
  File "/home/aldo/tweakersClone/src/venv_server/lib/python3.9/site-packages/interruptingcow/__init__.py", line 74, in handler
    raise exception
RuntimeError

2022-02-01 14:29:43,366 - INFO - Attempt 1 of activating geckodriver
2022-02-01 14:29:44,891 - ERROR - Geckodriver activation attempt 1 FAILED 
Traceback (most recent call last):
  File "/home/aldo/tweakersClone/src/webScraperCommon.py", line 208, in __init__
    self.driver = webdriver.Firefox(executable_path=self.pwd + self.geckodriverExe, options=self.firefox_options)
  File "/home/aldo/tweakersClone/src/venv_server/lib/python3.9/site-packages/selenium/webdriver/firefox/webdriver.py", line 154, in __init__
    RemoteWebDriver.__init__(
  File "/home/aldo/tweakersClone/src/venv_server/lib/python3.9/site-packages/selenium/webdriver/remote/webdriver.py", line 154, in __init__
    self.start_session(desired_capabilities, browser_profile)
  File "/home/aldo/tweakersClone/src/venv_server/lib/python3.9/site-packages/selenium/webdriver/remote/webdriver.py", line 243, in start_session
    response = self.execute(Command.NEW_SESSION, parameters)
  File "/home/aldo/tweakersClone/src/venv_server/lib/python3.9/site-packages/selenium/webdriver/remote/webdriver.py", line 311, in execute
    self.error_handler.check_response(response)
  File "/home/aldo/tweakersClone/src/venv_server/lib/python3.9/site-packages/selenium/webdriver/remote/errorhandler.py", line 237, in check_response
    raise exception_class(message, screen, stacktrace)
selenium.common.exceptions.WebDriverException: Message: Process unexpectedly closed with status 1


2022-02-01 14:29:44,894 - INFO - Attempt 2 of activating geckodriver
2022-02-01 14:29:46,271 - ERROR - Geckodriver activation attempt 2 FAILED 
Traceback (most recent call last):
  File "/home/aldo/tweakersClone/src/webScraperCommon.py", line 208, in __init__
    self.driver = webdriver.Firefox(executable_path=self.pwd + self.geckodriverExe, options=self.firefox_options)
  File "/home/aldo/tweakersClone/src/venv_server/lib/python3.9/site-packages/selenium/webdriver/firefox/webdriver.py", line 154, in __init__
    RemoteWebDriver.__init__(
  File "/home/aldo/tweakersClone/src/venv_server/lib/python3.9/site-packages/selenium/webdriver/remote/webdriver.py", line 154, in __init__
    self.start_session(desired_capabilities, browser_profile)
  File "/home/aldo/tweakersClone/src/venv_server/lib/python3.9/site-packages/selenium/webdriver/remote/webdriver.py", line 243, in start_session
    response = self.execute(Command.NEW_SESSION, parameters)
  File "/home/aldo/tweakersClone/src/venv_server/lib/python3.9/site-packages/selenium/webdriver/remote/webdriver.py", line 311, in execute
    self.error_handler.check_response(response)
  File "/home/aldo/tweakersClone/src/venv_server/lib/python3.9/site-packages/selenium/webdriver/remote/errorhandler.py", line 237, in check_response
    raise exception_class(message, screen, stacktrace)
selenium.common.exceptions.WebDriverException: Message: Process unexpectedly closed with status 1


2022-02-01 14:29:46,277 - INFO - Attempt 3 of activating geckodriver
2022-02-01 14:29:47,649 - ERROR - Geckodriver activation attempt 3 FAILED 
Traceback (most recent call last):
  File "/home/aldo/tweakersClone/src/webScraperCommon.py", line 208, in __init__
    self.driver = webdriver.Firefox(executable_path=self.pwd + self.geckodriverExe, options=self.firefox_options)
  File "/home/aldo/tweakersClone/src/venv_server/lib/python3.9/site-packages/selenium/webdriver/firefox/webdriver.py", line 154, in __init__
    RemoteWebDriver.__init__(
  File "/home/aldo/tweakersClone/src/venv_server/lib/python3.9/site-packages/selenium/webdriver/remote/webdriver.py", line 154, in __init__
    self.start_session(desired_capabilities, browser_profile)
  File "/home/aldo/tweakersClone/src/venv_server/lib/python3.9/site-packages/selenium/webdriver/remote/webdriver.py", line 243, in start_session
    response = self.execute(Command.NEW_SESSION, parameters)
  File "/home/aldo/tweakersClone/src/venv_server/lib/python3.9/site-packages/selenium/webdriver/remote/webdriver.py", line 311, in execute
    self.error_handler.check_response(response)
  File "/home/aldo/tweakersClone/src/venv_server/lib/python3.9/site-packages/selenium/webdriver/remote/errorhandler.py", line 237, in check_response
    raise exception_class(message, screen, stacktrace)
selenium.common.exceptions.WebDriverException: Message: Process unexpectedly closed with status 1


2022-02-01 14:29:47,657 - ERROR - Max attempts to turn on geckodriver reached, traceback: 
Traceback (most recent call last):
  File "/home/aldo/tweakersClone/src/webScraperCommon.py", line 208, in __init__
    self.driver = webdriver.Firefox(executable_path=self.pwd + self.geckodriverExe, options=self.firefox_options)
  File "/home/aldo/tweakersClone/src/venv_server/lib/python3.9/site-packages/selenium/webdriver/firefox/webdriver.py", line 154, in __init__
    RemoteWebDriver.__init__(
  File "/home/aldo/tweakersClone/src/venv_server/lib/python3.9/site-packages/selenium/webdriver/remote/webdriver.py", line 154, in __init__
    self.start_session(desired_capabilities, browser_profile)
  File "/home/aldo/tweakersClone/src/venv_server/lib/python3.9/site-packages/selenium/webdriver/remote/webdriver.py", line 243, in start_session
    response = self.execute(Command.NEW_SESSION, parameters)
  File "/home/aldo/tweakersClone/src/venv_server/lib/python3.9/site-packages/selenium/webdriver/remote/webdriver.py", line 311, in execute
    self.error_handler.check_response(response)
  File "/home/aldo/tweakersClone/src/venv_server/lib/python3.9/site-packages/selenium/webdriver/remote/errorhandler.py", line 237, in check_response
    raise exception_class(message, screen, stacktrace)
selenium.common.exceptions.WebDriverException: Message: Process unexpectedly closed with status 1


2022-02-01 14:33:26,363 - INFO - Attempt 1 of activating geckodriver
2022-02-01 14:33:27,603 - ERROR - Geckodriver activation attempt 1 FAILED 
Traceback (most recent call last):
  File "/home/aldo/tweakersClone/src/webScraperCommon.py", line 208, in __init__
    self.driver = webdriver.Firefox(executable_path=self.pwd + self.geckodriverExe, options=self.firefox_options)
  File "/home/aldo/tweakersClone/src/venv_server/lib/python3.9/site-packages/selenium/webdriver/firefox/webdriver.py", line 154, in __init__
    RemoteWebDriver.__init__(
  File "/home/aldo/tweakersClone/src/venv_server/lib/python3.9/site-packages/selenium/webdriver/remote/webdriver.py", line 154, in __init__
    self.start_session(desired_capabilities, browser_profile)
  File "/home/aldo/tweakersClone/src/venv_server/lib/python3.9/site-packages/selenium/webdriver/remote/webdriver.py", line 243, in start_session
    response = self.execute(Command.NEW_SESSION, parameters)
  File "/home/aldo/tweakersClone/src/venv_server/lib/python3.9/site-packages/selenium/webdriver/remote/webdriver.py", line 311, in execute
    self.error_handler.check_response(response)
  File "/home/aldo/tweakersClone/src/venv_server/lib/python3.9/site-packages/selenium/webdriver/remote/errorhandler.py", line 237, in check_response
    raise exception_class(message, screen, stacktrace)
selenium.common.exceptions.WebDriverException: Message: Process unexpectedly closed with status 1


2022-02-01 14:33:27,605 - INFO - Attempt 2 of activating geckodriver
2022-02-01 14:33:28,743 - ERROR - Geckodriver activation attempt 2 FAILED 
Traceback (most recent call last):
  File "/home/aldo/tweakersClone/src/webScraperCommon.py", line 208, in __init__
    self.driver = webdriver.Firefox(executable_path=self.pwd + self.geckodriverExe, options=self.firefox_options)
  File "/home/aldo/tweakersClone/src/venv_server/lib/python3.9/site-packages/selenium/webdriver/firefox/webdriver.py", line 154, in __init__
    RemoteWebDriver.__init__(
  File "/home/aldo/tweakersClone/src/venv_server/lib/python3.9/site-packages/selenium/webdriver/remote/webdriver.py", line 154, in __init__
    self.start_session(desired_capabilities, browser_profile)
  File "/home/aldo/tweakersClone/src/venv_server/lib/python3.9/site-packages/selenium/webdriver/remote/webdriver.py", line 243, in start_session
    response = self.execute(Command.NEW_SESSION, parameters)
  File "/home/aldo/tweakersClone/src/venv_server/lib/python3.9/site-packages/selenium/webdriver/remote/webdriver.py", line 311, in execute
    self.error_handler.check_response(response)
  File "/home/aldo/tweakersClone/src/venv_server/lib/python3.9/site-packages/selenium/webdriver/remote/errorhandler.py", line 237, in check_response
    raise exception_class(message, screen, stacktrace)
selenium.common.exceptions.WebDriverException: Message: Process unexpectedly closed with status 1


2022-02-01 14:33:28,745 - INFO - Attempt 3 of activating geckodriver
2022-02-01 14:33:29,880 - ERROR - Geckodriver activation attempt 3 FAILED 
Traceback (most recent call last):
  File "/home/aldo/tweakersClone/src/webScraperCommon.py", line 208, in __init__
    self.driver = webdriver.Firefox(executable_path=self.pwd + self.geckodriverExe, options=self.firefox_options)
  File "/home/aldo/tweakersClone/src/venv_server/lib/python3.9/site-packages/selenium/webdriver/firefox/webdriver.py", line 154, in __init__
    RemoteWebDriver.__init__(
  File "/home/aldo/tweakersClone/src/venv_server/lib/python3.9/site-packages/selenium/webdriver/remote/webdriver.py", line 154, in __init__
    self.start_session(desired_capabilities, browser_profile)
  File "/home/aldo/tweakersClone/src/venv_server/lib/python3.9/site-packages/selenium/webdriver/remote/webdriver.py", line 243, in start_session
    response = self.execute(Command.NEW_SESSION, parameters)
  File "/home/aldo/tweakersClone/src/venv_server/lib/python3.9/site-packages/selenium/webdriver/remote/webdriver.py", line 311, in execute
    self.error_handler.check_response(response)
  File "/home/aldo/tweakersClone/src/venv_server/lib/python3.9/site-packages/selenium/webdriver/remote/errorhandler.py", line 237, in check_response
    raise exception_class(message, screen, stacktrace)
selenium.common.exceptions.WebDriverException: Message: Process unexpectedly closed with status 1


2022-02-01 14:33:29,882 - ERROR - Max attempts to turn on geckodriver reached, traceback: 
Traceback (most recent call last):
  File "/home/aldo/tweakersClone/src/webScraperCommon.py", line 208, in __init__
    self.driver = webdriver.Firefox(executable_path=self.pwd + self.geckodriverExe, options=self.firefox_options)
  File "/home/aldo/tweakersClone/src/venv_server/lib/python3.9/site-packages/selenium/webdriver/firefox/webdriver.py", line 154, in __init__
    RemoteWebDriver.__init__(
  File "/home/aldo/tweakersClone/src/venv_server/lib/python3.9/site-packages/selenium/webdriver/remote/webdriver.py", line 154, in __init__
    self.start_session(desired_capabilities, browser_profile)
  File "/home/aldo/tweakersClone/src/venv_server/lib/python3.9/site-packages/selenium/webdriver/remote/webdriver.py", line 243, in start_session
    response = self.execute(Command.NEW_SESSION, parameters)
  File "/home/aldo/tweakersClone/src/venv_server/lib/python3.9/site-packages/selenium/webdriver/remote/webdriver.py", line 311, in execute
    self.error_handler.check_response(response)
  File "/home/aldo/tweakersClone/src/venv_server/lib/python3.9/site-packages/selenium/webdriver/remote/errorhandler.py", line 237, in check_response
    raise exception_class(message, screen, stacktrace)
selenium.common.exceptions.WebDriverException: Message: Process unexpectedly closed with status 1


2022-02-01 14:46:48,048 - INFO - Attempt 1 of activating geckodriver
2022-02-01 14:46:49,408 - ERROR - Geckodriver activation attempt 1 FAILED 
Traceback (most recent call last):
  File "/home/aldo/tweakersClone/src/webScraperCommon.py", line 208, in __init__
    self.driver = webdriver.Firefox(executable_path=self.pwd + self.geckodriverExe, options=self.firefox_options)
  File "/home/aldo/tweakersClone/src/venv_server/lib/python3.9/site-packages/selenium/webdriver/firefox/webdriver.py", line 154, in __init__
    RemoteWebDriver.__init__(
  File "/home/aldo/tweakersClone/src/venv_server/lib/python3.9/site-packages/selenium/webdriver/remote/webdriver.py", line 154, in __init__
    self.start_session(desired_capabilities, browser_profile)
  File "/home/aldo/tweakersClone/src/venv_server/lib/python3.9/site-packages/selenium/webdriver/remote/webdriver.py", line 243, in start_session
    response = self.execute(Command.NEW_SESSION, parameters)
  File "/home/aldo/tweakersClone/src/venv_server/lib/python3.9/site-packages/selenium/webdriver/remote/webdriver.py", line 311, in execute
    self.error_handler.check_response(response)
  File "/home/aldo/tweakersClone/src/venv_server/lib/python3.9/site-packages/selenium/webdriver/remote/errorhandler.py", line 237, in check_response
    raise exception_class(message, screen, stacktrace)
selenium.common.exceptions.WebDriverException: Message: Process unexpectedly closed with status 1


2022-02-01 14:46:49,411 - INFO - Attempt 2 of activating geckodriver
2022-02-01 14:46:50,556 - ERROR - Geckodriver activation attempt 2 FAILED 
Traceback (most recent call last):
  File "/home/aldo/tweakersClone/src/webScraperCommon.py", line 208, in __init__
    self.driver = webdriver.Firefox(executable_path=self.pwd + self.geckodriverExe, options=self.firefox_options)
  File "/home/aldo/tweakersClone/src/venv_server/lib/python3.9/site-packages/selenium/webdriver/firefox/webdriver.py", line 154, in __init__
    RemoteWebDriver.__init__(
  File "/home/aldo/tweakersClone/src/venv_server/lib/python3.9/site-packages/selenium/webdriver/remote/webdriver.py", line 154, in __init__
    self.start_session(desired_capabilities, browser_profile)
  File "/home/aldo/tweakersClone/src/venv_server/lib/python3.9/site-packages/selenium/webdriver/remote/webdriver.py", line 243, in start_session
    response = self.execute(Command.NEW_SESSION, parameters)
  File "/home/aldo/tweakersClone/src/venv_server/lib/python3.9/site-packages/selenium/webdriver/remote/webdriver.py", line 311, in execute
    self.error_handler.check_response(response)
  File "/home/aldo/tweakersClone/src/venv_server/lib/python3.9/site-packages/selenium/webdriver/remote/errorhandler.py", line 237, in check_response
    raise exception_class(message, screen, stacktrace)
selenium.common.exceptions.WebDriverException: Message: Process unexpectedly closed with status 1


2022-02-01 14:46:50,560 - INFO - Attempt 3 of activating geckodriver
2022-02-01 14:46:51,703 - ERROR - Geckodriver activation attempt 3 FAILED 
Traceback (most recent call last):
  File "/home/aldo/tweakersClone/src/webScraperCommon.py", line 208, in __init__
    self.driver = webdriver.Firefox(executable_path=self.pwd + self.geckodriverExe, options=self.firefox_options)
  File "/home/aldo/tweakersClone/src/venv_server/lib/python3.9/site-packages/selenium/webdriver/firefox/webdriver.py", line 154, in __init__
    RemoteWebDriver.__init__(
  File "/home/aldo/tweakersClone/src/venv_server/lib/python3.9/site-packages/selenium/webdriver/remote/webdriver.py", line 154, in __init__
    self.start_session(desired_capabilities, browser_profile)
  File "/home/aldo/tweakersClone/src/venv_server/lib/python3.9/site-packages/selenium/webdriver/remote/webdriver.py", line 243, in start_session
    response = self.execute(Command.NEW_SESSION, parameters)
  File "/home/aldo/tweakersClone/src/venv_server/lib/python3.9/site-packages/selenium/webdriver/remote/webdriver.py", line 311, in execute
    self.error_handler.check_response(response)
  File "/home/aldo/tweakersClone/src/venv_server/lib/python3.9/site-packages/selenium/webdriver/remote/errorhandler.py", line 237, in check_response
    raise exception_class(message, screen, stacktrace)
selenium.common.exceptions.WebDriverException: Message: Process unexpectedly closed with status 1


2022-02-01 14:46:51,713 - ERROR - Max attempts to turn on geckodriver reached, traceback: 
Traceback (most recent call last):
  File "/home/aldo/tweakersClone/src/webScraperCommon.py", line 208, in __init__
    self.driver = webdriver.Firefox(executable_path=self.pwd + self.geckodriverExe, options=self.firefox_options)
  File "/home/aldo/tweakersClone/src/venv_server/lib/python3.9/site-packages/selenium/webdriver/firefox/webdriver.py", line 154, in __init__
    RemoteWebDriver.__init__(
  File "/home/aldo/tweakersClone/src/venv_server/lib/python3.9/site-packages/selenium/webdriver/remote/webdriver.py", line 154, in __init__
    self.start_session(desired_capabilities, browser_profile)
  File "/home/aldo/tweakersClone/src/venv_server/lib/python3.9/site-packages/selenium/webdriver/remote/webdriver.py", line 243, in start_session
    response = self.execute(Command.NEW_SESSION, parameters)
  File "/home/aldo/tweakersClone/src/venv_server/lib/python3.9/site-packages/selenium/webdriver/remote/webdriver.py", line 311, in execute
    self.error_handler.check_response(response)
  File "/home/aldo/tweakersClone/src/venv_server/lib/python3.9/site-packages/selenium/webdriver/remote/errorhandler.py", line 237, in check_response
    raise exception_class(message, screen, stacktrace)
selenium.common.exceptions.WebDriverException: Message: Process unexpectedly closed with status 1


2022-02-01 14:47:20,915 - INFO - Attempt 1 of activating geckodriver
2022-02-01 14:47:22,043 - ERROR - Geckodriver activation attempt 1 FAILED 
Traceback (most recent call last):
  File "/home/aldo/tweakersClone/src/webScraperCommon.py", line 208, in __init__
    self.driver = webdriver.Firefox(executable_path=self.pwd + self.geckodriverExe, options=self.firefox_options)
  File "/home/aldo/tweakersClone/src/venv_server/lib/python3.9/site-packages/selenium/webdriver/firefox/webdriver.py", line 154, in __init__
    RemoteWebDriver.__init__(
  File "/home/aldo/tweakersClone/src/venv_server/lib/python3.9/site-packages/selenium/webdriver/remote/webdriver.py", line 154, in __init__
    self.start_session(desired_capabilities, browser_profile)
  File "/home/aldo/tweakersClone/src/venv_server/lib/python3.9/site-packages/selenium/webdriver/remote/webdriver.py", line 243, in start_session
    response = self.execute(Command.NEW_SESSION, parameters)
  File "/home/aldo/tweakersClone/src/venv_server/lib/python3.9/site-packages/selenium/webdriver/remote/webdriver.py", line 311, in execute
    self.error_handler.check_response(response)
  File "/home/aldo/tweakersClone/src/venv_server/lib/python3.9/site-packages/selenium/webdriver/remote/errorhandler.py", line 237, in check_response
    raise exception_class(message, screen, stacktrace)
selenium.common.exceptions.WebDriverException: Message: Process unexpectedly closed with status 1


2022-02-01 14:47:22,045 - INFO - Attempt 2 of activating geckodriver
2022-02-01 14:47:23,173 - ERROR - Geckodriver activation attempt 2 FAILED 
Traceback (most recent call last):
  File "/home/aldo/tweakersClone/src/webScraperCommon.py", line 208, in __init__
    self.driver = webdriver.Firefox(executable_path=self.pwd + self.geckodriverExe, options=self.firefox_options)
  File "/home/aldo/tweakersClone/src/venv_server/lib/python3.9/site-packages/selenium/webdriver/firefox/webdriver.py", line 154, in __init__
    RemoteWebDriver.__init__(
  File "/home/aldo/tweakersClone/src/venv_server/lib/python3.9/site-packages/selenium/webdriver/remote/webdriver.py", line 154, in __init__
    self.start_session(desired_capabilities, browser_profile)
  File "/home/aldo/tweakersClone/src/venv_server/lib/python3.9/site-packages/selenium/webdriver/remote/webdriver.py", line 243, in start_session
    response = self.execute(Command.NEW_SESSION, parameters)
  File "/home/aldo/tweakersClone/src/venv_server/lib/python3.9/site-packages/selenium/webdriver/remote/webdriver.py", line 311, in execute
    self.error_handler.check_response(response)
  File "/home/aldo/tweakersClone/src/venv_server/lib/python3.9/site-packages/selenium/webdriver/remote/errorhandler.py", line 237, in check_response
    raise exception_class(message, screen, stacktrace)
selenium.common.exceptions.WebDriverException: Message: Process unexpectedly closed with status 1


2022-02-01 14:47:23,175 - INFO - Attempt 3 of activating geckodriver
2022-02-01 14:47:24,301 - ERROR - Geckodriver activation attempt 3 FAILED 
Traceback (most recent call last):
  File "/home/aldo/tweakersClone/src/webScraperCommon.py", line 208, in __init__
    self.driver = webdriver.Firefox(executable_path=self.pwd + self.geckodriverExe, options=self.firefox_options)
  File "/home/aldo/tweakersClone/src/venv_server/lib/python3.9/site-packages/selenium/webdriver/firefox/webdriver.py", line 154, in __init__
    RemoteWebDriver.__init__(
  File "/home/aldo/tweakersClone/src/venv_server/lib/python3.9/site-packages/selenium/webdriver/remote/webdriver.py", line 154, in __init__
    self.start_session(desired_capabilities, browser_profile)
  File "/home/aldo/tweakersClone/src/venv_server/lib/python3.9/site-packages/selenium/webdriver/remote/webdriver.py", line 243, in start_session
    response = self.execute(Command.NEW_SESSION, parameters)
  File "/home/aldo/tweakersClone/src/venv_server/lib/python3.9/site-packages/selenium/webdriver/remote/webdriver.py", line 311, in execute
    self.error_handler.check_response(response)
  File "/home/aldo/tweakersClone/src/venv_server/lib/python3.9/site-packages/selenium/webdriver/remote/errorhandler.py", line 237, in check_response
    raise exception_class(message, screen, stacktrace)
selenium.common.exceptions.WebDriverException: Message: Process unexpectedly closed with status 1


2022-02-01 14:47:24,303 - ERROR - Max attempts to turn on geckodriver reached, traceback: 
Traceback (most recent call last):
  File "/home/aldo/tweakersClone/src/webScraperCommon.py", line 208, in __init__
    self.driver = webdriver.Firefox(executable_path=self.pwd + self.geckodriverExe, options=self.firefox_options)
  File "/home/aldo/tweakersClone/src/venv_server/lib/python3.9/site-packages/selenium/webdriver/firefox/webdriver.py", line 154, in __init__
    RemoteWebDriver.__init__(
  File "/home/aldo/tweakersClone/src/venv_server/lib/python3.9/site-packages/selenium/webdriver/remote/webdriver.py", line 154, in __init__
    self.start_session(desired_capabilities, browser_profile)
  File "/home/aldo/tweakersClone/src/venv_server/lib/python3.9/site-packages/selenium/webdriver/remote/webdriver.py", line 243, in start_session
    response = self.execute(Command.NEW_SESSION, parameters)
  File "/home/aldo/tweakersClone/src/venv_server/lib/python3.9/site-packages/selenium/webdriver/remote/webdriver.py", line 311, in execute
    self.error_handler.check_response(response)
  File "/home/aldo/tweakersClone/src/venv_server/lib/python3.9/site-packages/selenium/webdriver/remote/errorhandler.py", line 237, in check_response
    raise exception_class(message, screen, stacktrace)
selenium.common.exceptions.WebDriverException: Message: Process unexpectedly closed with status 1


2022-02-01 14:49:51,109 - INFO - Attempt 1 of activating geckodriver
2022-02-01 14:49:59,271 - ERROR - Geckodriver activation attempt 1 FAILED 
Traceback (most recent call last):
  File "/home/aldo/tweakersClone/src/webScraperCommon.py", line 208, in __init__
    self.driver = webdriver.Firefox(executable_path=self.pwd + self.geckodriverExe, options=self.firefox_options)
  File "/home/aldo/tweakersClone/src/venv_server/lib/python3.9/site-packages/selenium/webdriver/firefox/webdriver.py", line 154, in __init__
    RemoteWebDriver.__init__(
  File "/home/aldo/tweakersClone/src/venv_server/lib/python3.9/site-packages/selenium/webdriver/remote/webdriver.py", line 154, in __init__
    self.start_session(desired_capabilities, browser_profile)
  File "/home/aldo/tweakersClone/src/venv_server/lib/python3.9/site-packages/selenium/webdriver/remote/webdriver.py", line 243, in start_session
    response = self.execute(Command.NEW_SESSION, parameters)
  File "/home/aldo/tweakersClone/src/venv_server/lib/python3.9/site-packages/selenium/webdriver/remote/webdriver.py", line 309, in execute
    response = self.command_executor.execute(driver_command, params)
  File "/home/aldo/tweakersClone/src/venv_server/lib/python3.9/site-packages/selenium/webdriver/remote/remote_connection.py", line 460, in execute
    return self._request(command_info[0], url, body=data)
  File "/home/aldo/tweakersClone/src/venv_server/lib/python3.9/site-packages/selenium/webdriver/remote/remote_connection.py", line 484, in _request
    resp = self._conn.getresponse()
  File "/usr/lib/python3.9/http/client.py", line 1349, in getresponse
    response.begin()
  File "/usr/lib/python3.9/http/client.py", line 316, in begin
    version, status, reason = self._read_status()
  File "/usr/lib/python3.9/http/client.py", line 277, in _read_status
    line = str(self.fp.readline(_MAXLINE + 1), "iso-8859-1")
  File "/usr/lib/python3.9/socket.py", line 704, in readinto
    return self._sock.recv_into(b)
  File "/home/aldo/tweakersClone/src/venv_server/lib/python3.9/site-packages/interruptingcow/__init__.py", line 74, in handler
    raise exception
RuntimeError

2022-02-01 14:49:59,278 - INFO - Attempt 2 of activating geckodriver
2022-02-01 14:50:07,417 - ERROR - Geckodriver activation attempt 2 FAILED 
Traceback (most recent call last):
  File "/home/aldo/tweakersClone/src/webScraperCommon.py", line 208, in __init__
    self.driver = webdriver.Firefox(executable_path=self.pwd + self.geckodriverExe, options=self.firefox_options)
  File "/home/aldo/tweakersClone/src/venv_server/lib/python3.9/site-packages/selenium/webdriver/firefox/webdriver.py", line 154, in __init__
    RemoteWebDriver.__init__(
  File "/home/aldo/tweakersClone/src/venv_server/lib/python3.9/site-packages/selenium/webdriver/remote/webdriver.py", line 154, in __init__
    self.start_session(desired_capabilities, browser_profile)
  File "/home/aldo/tweakersClone/src/venv_server/lib/python3.9/site-packages/selenium/webdriver/remote/webdriver.py", line 243, in start_session
    response = self.execute(Command.NEW_SESSION, parameters)
  File "/home/aldo/tweakersClone/src/venv_server/lib/python3.9/site-packages/selenium/webdriver/remote/webdriver.py", line 309, in execute
    response = self.command_executor.execute(driver_command, params)
  File "/home/aldo/tweakersClone/src/venv_server/lib/python3.9/site-packages/selenium/webdriver/remote/remote_connection.py", line 460, in execute
    return self._request(command_info[0], url, body=data)
  File "/home/aldo/tweakersClone/src/venv_server/lib/python3.9/site-packages/selenium/webdriver/remote/remote_connection.py", line 484, in _request
    resp = self._conn.getresponse()
  File "/usr/lib/python3.9/http/client.py", line 1349, in getresponse
    response.begin()
  File "/usr/lib/python3.9/http/client.py", line 316, in begin
    version, status, reason = self._read_status()
  File "/usr/lib/python3.9/http/client.py", line 277, in _read_status
    line = str(self.fp.readline(_MAXLINE + 1), "iso-8859-1")
  File "/usr/lib/python3.9/socket.py", line 704, in readinto
    return self._sock.recv_into(b)
  File "/home/aldo/tweakersClone/src/venv_server/lib/python3.9/site-packages/interruptingcow/__init__.py", line 74, in handler
    raise exception
RuntimeError

2022-02-01 14:50:07,428 - INFO - Attempt 3 of activating geckodriver
2022-02-01 14:50:15,702 - ERROR - Geckodriver activation attempt 3 FAILED 
Traceback (most recent call last):
  File "/home/aldo/tweakersClone/src/webScraperCommon.py", line 208, in __init__
    self.driver = webdriver.Firefox(executable_path=self.pwd + self.geckodriverExe, options=self.firefox_options)
  File "/home/aldo/tweakersClone/src/venv_server/lib/python3.9/site-packages/selenium/webdriver/firefox/webdriver.py", line 154, in __init__
    RemoteWebDriver.__init__(
  File "/home/aldo/tweakersClone/src/venv_server/lib/python3.9/site-packages/selenium/webdriver/remote/webdriver.py", line 154, in __init__
    self.start_session(desired_capabilities, browser_profile)
  File "/home/aldo/tweakersClone/src/venv_server/lib/python3.9/site-packages/selenium/webdriver/remote/webdriver.py", line 243, in start_session
    response = self.execute(Command.NEW_SESSION, parameters)
  File "/home/aldo/tweakersClone/src/venv_server/lib/python3.9/site-packages/selenium/webdriver/remote/webdriver.py", line 309, in execute
    response = self.command_executor.execute(driver_command, params)
  File "/home/aldo/tweakersClone/src/venv_server/lib/python3.9/site-packages/selenium/webdriver/remote/remote_connection.py", line 460, in execute
    return self._request(command_info[0], url, body=data)
  File "/home/aldo/tweakersClone/src/venv_server/lib/python3.9/site-packages/selenium/webdriver/remote/remote_connection.py", line 484, in _request
    resp = self._conn.getresponse()
  File "/usr/lib/python3.9/http/client.py", line 1349, in getresponse
    response.begin()
  File "/usr/lib/python3.9/http/client.py", line 316, in begin
    version, status, reason = self._read_status()
  File "/usr/lib/python3.9/http/client.py", line 277, in _read_status
    line = str(self.fp.readline(_MAXLINE + 1), "iso-8859-1")
  File "/usr/lib/python3.9/socket.py", line 704, in readinto
    return self._sock.recv_into(b)
  File "/home/aldo/tweakersClone/src/venv_server/lib/python3.9/site-packages/interruptingcow/__init__.py", line 74, in handler
    raise exception
RuntimeError

2022-02-01 14:50:15,713 - ERROR - Max attempts to turn on geckodriver reached, traceback: 
Traceback (most recent call last):
  File "/home/aldo/tweakersClone/src/webScraperCommon.py", line 208, in __init__
    self.driver = webdriver.Firefox(executable_path=self.pwd + self.geckodriverExe, options=self.firefox_options)
  File "/home/aldo/tweakersClone/src/venv_server/lib/python3.9/site-packages/selenium/webdriver/firefox/webdriver.py", line 154, in __init__
    RemoteWebDriver.__init__(
  File "/home/aldo/tweakersClone/src/venv_server/lib/python3.9/site-packages/selenium/webdriver/remote/webdriver.py", line 154, in __init__
    self.start_session(desired_capabilities, browser_profile)
  File "/home/aldo/tweakersClone/src/venv_server/lib/python3.9/site-packages/selenium/webdriver/remote/webdriver.py", line 243, in start_session
    response = self.execute(Command.NEW_SESSION, parameters)
  File "/home/aldo/tweakersClone/src/venv_server/lib/python3.9/site-packages/selenium/webdriver/remote/webdriver.py", line 309, in execute
    response = self.command_executor.execute(driver_command, params)
  File "/home/aldo/tweakersClone/src/venv_server/lib/python3.9/site-packages/selenium/webdriver/remote/remote_connection.py", line 460, in execute
    return self._request(command_info[0], url, body=data)
  File "/home/aldo/tweakersClone/src/venv_server/lib/python3.9/site-packages/selenium/webdriver/remote/remote_connection.py", line 484, in _request
    resp = self._conn.getresponse()
  File "/usr/lib/python3.9/http/client.py", line 1349, in getresponse
    response.begin()
  File "/usr/lib/python3.9/http/client.py", line 316, in begin
    version, status, reason = self._read_status()
  File "/usr/lib/python3.9/http/client.py", line 277, in _read_status
    line = str(self.fp.readline(_MAXLINE + 1), "iso-8859-1")
  File "/usr/lib/python3.9/socket.py", line 704, in readinto
    return self._sock.recv_into(b)
  File "/home/aldo/tweakersClone/src/venv_server/lib/python3.9/site-packages/interruptingcow/__init__.py", line 74, in handler
    raise exception
RuntimeError

2022-02-01 14:54:22,281 - INFO - Attempt 1 of activating geckodriver
2022-02-01 14:54:28,353 - INFO - geckodriver successfully activated
2022-02-01 18:08:34,047 - INFO - Attempt 1 of activating geckodriver
2022-02-01 18:08:40,404 - INFO - geckodriver successfully activated
2022-02-01 18:08:52,290 - INFO - Attempt 1 of activating geckodriver
2022-02-01 18:08:57,786 - INFO - geckodriver successfully activated
2022-02-01 18:16:15,866 - INFO - Attempt 1 of activating geckodriver
2022-02-01 18:16:21,373 - INFO - geckodriver successfully activated
2022-02-01 18:16:40,542 - INFO - Attempt 1 of activating geckodriver
2022-02-01 18:16:45,566 - INFO - geckodriver successfully activated
2022-02-02 04:06:44,307 - ERROR - Credentials of database not available, traceback: 
Traceback (most recent call last):
  File "/home/aldo/tweakersClone/src/coolblueScraper.py", line 46, in main
    username = os.environ["tweakersCloneUsername"]
  File "/usr/lib/python3.9/os.py", line 679, in __getitem__
    raise KeyError(key) from None
KeyError: 'tweakersCloneUsername'

2022-02-02 10:53:14,305 - INFO - Attempt 1 of activating geckodriver
2022-02-02 10:53:20,408 - INFO - geckodriver successfully activated
2022-02-02 10:53:33,783 - INFO - Attempt 1 of activating geckodriver
2022-02-02 10:53:39,960 - INFO - geckodriver successfully activated
2022-02-02 11:04:12,549 - INFO - Attempt 1 of activating geckodriver
2022-02-02 11:04:19,818 - INFO - geckodriver successfully activated
2022-02-02 11:04:27,713 - INFO - Attempt 1 of activating geckodriver
2022-02-02 11:04:33,935 - INFO - geckodriver successfully activated
2022-02-02 11:10:26,213 - INFO - Attempt 1 of activating geckodriver
2022-02-02 11:10:33,262 - INFO - geckodriver successfully activated
2022-02-02 11:10:47,037 - INFO - Attempt 1 of activating geckodriver
2022-02-02 11:10:53,155 - INFO - geckodriver successfully activated
2022-02-02 13:22:26,125 - INFO - Attempt 1 of activating geckodriver
2022-02-02 13:22:33,432 - INFO - geckodriver successfully activated
2022-02-02 13:22:41,953 - INFO - Attempt 1 of activating geckodriver
2022-02-02 13:22:47,657 - INFO - geckodriver successfully activated
2022-02-02 13:22:57,985 - INFO - Attempt 1 of activating geckodriver
2022-02-02 13:23:04,482 - INFO - geckodriver successfully activated
2022-02-02 13:23:10,161 - INFO - Attempt 1 of activating geckodriver
2022-02-02 13:23:16,297 - INFO - geckodriver successfully activated
2022-02-02 13:23:23,457 - INFO - Attempt 1 of activating geckodriver
2022-02-02 13:23:29,753 - INFO - geckodriver successfully activated
2022-02-02 14:39:34,161 - INFO - Attempt 1 of activating geckodriver
2022-02-02 14:39:40,841 - INFO - geckodriver successfully activated
2022-02-02 14:39:49,822 - INFO - Attempt 1 of activating geckodriver
2022-02-02 14:39:55,541 - INFO - geckodriver successfully activated
2022-02-02 14:40:06,826 - INFO - Attempt 1 of activating geckodriver
2022-02-02 14:40:13,027 - INFO - geckodriver successfully activated
2022-02-02 14:40:23,843 - INFO - Attempt 1 of activating geckodriver
2022-02-02 14:40:29,859 - INFO - geckodriver successfully activated
2022-02-02 14:40:38,934 - INFO - Attempt 1 of activating geckodriver
2022-02-02 14:40:45,402 - INFO - geckodriver successfully activated
